Workbook

Sheet Volume estimator
H1: packet size (bits)
I2: historical size | J2: # of power cycles | K2: integration time (s) | L2: bps | M2: sec/day | N2: data collection (days) | P2: Total recorded data (Mbits) | Q2: Total downlinked data (Mbits)
F3: Data Generated during Power Cycle
G4: Data sent to Recorder | I4: 1.579 | J4: 1 | P4: =I4*J4 -> 1.579
G5: Data sent to the Ground | I5: 1.483 | J5: 1 | Q5: =I5*J5 -> 1.483
H7: max bits | I7: historical size | J7: Enabled? | K7: integration time (s) | L7: bps | M7: sec/day | N7: data collection (days) | P7: Total recorded data (Mbits) | Q7: Total downlinked data (Mbits)
F8: Survey Data
G9: N1 | H9: 5680 | I9: 2400 | J9: 1 | K9: 180 | L9: =J9*I9/K9 -> 13.333333 | M9: =3600*24 -> 86400 | N9: 14.5 | P9: =L9*M9*N9/1000000 -> 16.704 | Q9: =P9 -> 16.704
G10: N2 normal | H10: 4928 | I10: 1920 | J10: 0 | K10: 180 | L10: =J10*I10/K10 -> 0 | M10: =3600*24 -> 86400 | N10: 14.5 | P10: =L10*M10*N10*O10/1000000 -> 0 | Q10: =P10 -> 0
G11: N3+ extra | H11: 64000 | I11: 20000 | J11: 1 | K11: 7200 | L11: =J11*I11/K11 -> 2.7777778 | M11: =3600*24 -> 86400 | N11: 14.5 | P11: =L11*M11*N11/1000000 -> 3.48 | Q11: =P11 -> 3.48
G12: HK/status | H12: 512 | I12: =H12 -> 512 | J12: 1 | K12: 1800 | L12: =J12*I12/K12 -> 0.28444444 | M12: =3600*24 -> 86400 | N12: 14.5 | P12: =L12*M12*N12/1000000 -> 0.356352 | Q12: =P12 -> 0.356352
H13: =E12/30 -> 0 | K13: =IF(AND( (K9/K10)=INT(K9/K10), (K11/K10)=INT(K11/K10) ), " ", "error") | P13: =SUM(P9:P12) -> 20.540352 | Q13: =SUM(Q9:Q12) -> 20.540352
H15: max bits | I15: historical size | J15: Enabled? | K15: integration time (s) | L15: bps | M15: sec/day | N15: data collection (days) | O15: months/ year | P15: Total recorded data (Mbits) | Q15: Total downlinked data (Mbits)
F16: Burst Data
G17: High Time Resolution Buffered Rate (10) Data | H17: ='Packet size and rates'!AA52 -> 8480 | I17: 2900 | J17: 1 | K17: =I25*64 -> 1280 | L17: =J17*I17/K17 -> 2.265625 | M17: =3600*24 -> 86400 | N17: =I28*(I26+I27) -> 20.4 | P17: =L17*M17*I28*((I26+I27))/1000000 -> 3.9933 | Q17: =L17*M17*I29*((I26+I27))/1000000 -> 0.66555
G18: Trigger assessment data | H18: ='Packet size and rates'!U52 -> 992 | I18: 600 | J18: 1 | K18: =I25*64 -> 1280 | L18: =J18*I18/K18 -> 0.46875 | M18: =3600*24 -> 86400 | N18: =I29*(I26+I27) -> 3.4 | P18: =L18*M18*I28*((I26+I27))/1000000 -> 0.8262 | Q18: =L18*M18*I28*((I26+I27))/1000000 -> 0.8262
G19: N2 burst data | H19: =H10 -> 4928 | I19: 1400 | J19: 1 | K19: =I25 -> 20 | L19: =J19*I19/K19 -> 70 | M19: =3600*24 -> 86400 | N19: =I29*I27 -> 2 | P19: =L19*M19*I28*I27/1000000 -> 72.576 | Q19: =L19*M19*I29*I27/1000000 -> 12.096
P20: =SUM(P17:P19) -> 77.3955 | Q20: =SUM(Q17:Q19) -> 13.58775
F22: Total | P22: =P4+P13+P20 -> 99.514852 | Q22: =Q5+Q13+Q20 -> 35.611102 | R22: Mbits
F24: Assumptions
F25: Commanded N2Monitor int time | I25: 20 | P25: Total for hibernation period | R25: =P22 -> 99.514852 | S25: Mbit
F26: pre-trigger data (days) | I26: =0.7*I25/10 -> 1.4
F27: post-trigger data (days) | I27: 2
F28: Number of bursts occurring in this period | I28: 6
F29: # of N2 bursts downlinked in this period | I29: 1

Sheet Packet size and rates
D3: 0x694 Medium Prior N2 | I3: 0x691 High Prior N1 | L3: 0x693 Low Prior N3 | P3: 0x694 Low Prior N3 | T3: 0x68A Trig Assess. | Y3: 0x699 Pre-Trigger Dat
B5: Version | D5: 3 | I5: 3 | L5: 3 | P5: 3 | U5: 3 | AA5: =U5 -> 3
B6: Type | D6: 1 | I6: 1 | L6: 1 | P6: 1 | U6: 1 | AA6: =U6 -> 1
B7: Secondary? | D7: 1 | I7: 1 | L7: 1 | P7: 1 | U7: 1 | AA7: =U7 -> 1
B8: App ID | D8: 11 | I8: 11 | L8: 11 | P8: 11 | U8: 11 | AA8: =U8 -> 11
B9: Grouping | D9: 2 | I9: 2 | L9: 2 | P9: 2 | U9: 2 | AA9: =U9 -> 2
B10: Sequence Count | D10: 14 | I10: 14 | L10: 14 | P10: 14 | U10: 14 | AA10: =U10 -> 14
B11: Length | D11: 16 | I11: 16 | L11: 16 | P11: 16 | U11: 16 | AA11: =U11 -> 16
B12: Secondary Header | D12: 32 | I12: 32 | L12: 32 | P12: 32 | U12: 32 | AA12: =U12 -> 32
D14: 1824 | I14: 1824 | L14: 32000 | P14: 32000 | T14: Header total | U14: =SUM(U5:U13) -> 80 | AA14: =U14 -> 80
D15: 144 | I15: 144
D16: 896 | I16: 1792 | S16: Data Header | Y16: Data Header
D17: 384 | I17: 512 | T17: Ring buffer slot | U17: 16 | Z17: Ring buffer slot | AA17: 16
I18: 528 | T18: Payload length | U18: 16 | Z18: Payload length | AA18: 16
D19: 1600 | I19: 800 | T19: Last capture time | U19: 32 | Z19: Last capture time | AA19: 32
T20: Blocks (aka Chunks) | U20: 16 | Z20: Blocks (aka Chunks) | AA20: 16
T21: Data Header Subtotal | U21: =SUM(U17:U20) -> 80 | Z21: Data Header Subtotal | AA21: =SUM(AA17:AA20) -> 80
D22: =SUM(D5:D19) -> 4928 | I22: =SUM(I5:I20) -> 5680 | L22: =SUM(L5:L20) -> 32080 | P22: =SUM(P5:P20) -> 32080
T24: 16 values compressed
I25: N1= N2 * X | S25: Each block:
T26: # bytes in block | U26: 8 | AA26: =U26 -> 8
T27: #bits | U27: 8 | V27: (<--this is the max size, but typically fewer) | AA27: =U27 -> 8
T28: initial | U28: 16 | AA28: =U28 -> 16
F29: =3600*24 -> 86400 | I29: =1896/60/30 -> 1.0533333 | U29: 11 | V29: (<--this is the max size, but typically fewer) | AA29: =U29 -> 11
U30: 11 | V30: " | AA30: =U30 -> 11
U31: 11 | V31: " | AA31: =U31 -> 11
U32: 11 | V32: " | AA32: =U32 -> 11
U33: 11 | V33: " | AA33: =U33 -> 11
U34: 11 | V34: " | AA34: =U34 -> 11
U35: 11 | V35: " | AA35: =U35 -> 11
U36: 11 | V36: " | AA36: =U36 -> 11
U37: 11 | V37: " | AA37: =U37 -> 11
U38: 11 | V38: " | AA38: =U38 -> 11
U39: 11 | V39: " | AA39: =U39 -> 11
U40: 11 | V40: " | AA40: =U40 -> 11
U41: 11 | V41: " | AA41: =U41 -> 11
... U43: 11 | V43: " | AA43: =U43 -> 11
U44: =SUM(U26:U43) -> 197 | AA44: =U44 -> 197
T46: padding | U46: 11 | V46: (<--this is the max size, but typically fewer) | AA46: =U46 -> 11
B48: Packet Accum Time | D48: 20 | I48: =3600*4 -> 14400 | L48: =3600*4 -> 14400 | P48: =3600*4 -> 14400 | R48: worst case | T48: Block total | U48: =U44+U46 -> 208 | V48: (<--this is the max size, but typically fewer) | AA48: =U48 -> 208
...

Sheet hibernation_yearly
C3: Load number: | E3: 24267
C4: First | E4: DOY | F4: Hour | G4: Min | H4: Days: | I4: Delta | K4: Burst enabled?
D5: Start: | E5: 0 | F5: 0 | G5: 0 | H5: =E5+(F5+G5/60)/24 -> 0
D6: Stop: | E6: 365 | F6: 0 | G6: 0 | H6: =E6+(F6+G6/60)/24 -> 365 | I6: =H6-H5 -> 365 | K6: yes
C7: Second | O7: The fields in blue need to be updated for each load
D8: Start:
D9: Stop:
C11: How many power-on instances are in this load?: | G11: 1
D13: Settings:
E14: N1 | F14: 180
E15: Macro 103/104? | F15: 103 | G15: --> | H15: N2mon = | I15: =IF(F16=101,3,IF(F15=103,3,2)) -> 3
E16: Macro 105-110? | F16: 101 | H16: macro used= | I16: =IF(F16=101,106, F16) -> 106 | J16: <-- if macro=101, then macro 103/104 field is ignored, and settings for macro 103/106 are automatically used
E17: N3 | F17: 7200
E18: Status | F18: 1800
L19: Science
D20: Telemetry product: | H20: Days | I20: Mbits/day | J20: Total Mbits | K20: bps | L20: bytes/s
E21: N1 | F21: 0x691 | H21: =I$6+I$9 -> 365 | I21: =IF(I15=2,(VLOOKUP($I$16,'Packet size and rates'!G110:AH115, 16,FALSE())), (VLOOKUP($I$16,'Packet size and rates'!G103:AH108, 16,FALSE())))*('Packet size and rates'!V117/F14) -> 0.95424 | J21: =H21*I21 -> 348.2976 | K21: =1000000*I21/(24*3600) -> 11.044444 | L21: =K21/8 -> 1.3805556 | M21: PEPSSI_DT1
E22: N3 | F22: 0x693 | H22: =I$6+I$9 -> 365 | I22: =IF(I15=2,(VLOOKUP($I$16,'Packet size and rates'!G110:AH115, 19,FALSE())), (VLOOKUP($I$16,'Packet size and rates'!G103:AH108, 19,FALSE())))*('Packet size and rates'!Y117/F17) -> 0.218112 | J22: =H22*I22 -> 79.61088 | K22: =1000000*I22/(24*3600) -> 2.5244444 | L22: =K22/8 -> 0.31555556 | M22: PEPSSI_DT2
E23: Status | F23: 0x685 | H23: =I$6+I$9 -> 365 | I23: =IF(I15=2,(VLOOKUP($I$16,'Packet size and rates'!G110:AH115, 13,FALSE())), (VLOOKUP($I$16,'Packet size and rates'!G103:AH108, 13,FALSE())))*('Packet size and rates'!S117/F18) -> 0.024576 | J23: =H23*I23 -> 8.97024 | K23: =1000000*I23/(24*3600) -> 0.28444444 | L23: =K23/8 -> 0.035555556 | M23: INST_HSK_3
E24: N2 | F24: 0x692 | H24: =IF(K$9="yes",I$9,0)+IF(K$6="yes",I$6,0) -> 365 | I24: =IF(I15=2,(VLOOKUP($I$16,'Packet size and rates'!G110:AH115, 25,FALSE())), (VLOOKUP($I$16,'Packet size and rates'!G103:AH108, 25,FALSE()))) -> 0.5064 | J24: =H24*I24 -> 184.836 | K24: =1000000*I24/(24*3600) -> 5.8611111 | L24: =K24/8 -> 0.73263889 | M24: PEPSSI_DT3
E25: Trigger packet | F25: 0x68A | H25: =IF(K$9="yes",I$9,0)+IF(K$6="yes",I$6,0) -> 365 | I25: =IF(I15=2,(VLOOKUP($I$16,'Packet size and rates'!G110:AH115, 5,FALSE())), (VLOOKUP($I$16,'Packet size and rates'!G103:AH108, 5,FALSE()))) -> 0.2367 | J25: =H25*I25 -> 86.3955 | K25: =1000000*I25/(24*3600) -> 2.7395833 | L25: =K25/8 -> 0.34244792 | M25: PEPSSI_DT4
E26: Buffered Rates | F26: 0x697 | H26: =IF(K$9="yes",I$9,0)+IF(K$6="yes",I$6,0) -> 365 | I26: =IF(I15=2,(VLOOKUP($I$16,'Packet size and rates'!G110:AH115, 8,FALSE())), (VLOOKUP($I$16,'Packet size and rates'!G103:AH108, 8,FALSE()))) -> 0.93915 | J26: =H26*I26 -> 342.78975 | K26: =1000000*I26/(24*3600) -> 10.869792 | L26: =K26/8 -> 1.358724 | M26: DT2 if Mac102, otherwise DT3
E27: SubTotal | I27: =SUM(I21:I26) -> 2.879178 | J27: =SUM(J21:J26) -> 1050.9 | K27: =SUM(K21:K26) -> 33.323819 | L27: =SUM(L21:L26) -> 4.1654774
E29: Power-on | J29: =1.6*G11 -> 1.6
E31: Total | J31: =J27+J29 -> 1052.5
I33: Mbits/day | J33: Mbits | K33: bps | L33: bytes/s
H34: N1/N3/Status | I34: =I21+I22+I23 -> 1.196928 | J34: =J21+J22+J23 -> 436.87872 | K34: =K21+K22+K23 -> 13.853333 | L34: =L21+L22+L23 -> 1.7316667 | M34: DT1, DT2, HSK3
H35: buff rates + N1/N3/Status | I35: =I26+I23+I22+I21 -> 2.136078 | J35: =J26+J23+J22+J21 -> 779.66847 | K35: =K26+K23+K22+K21 -> 24.723125 | L35: =L26+L23+L22+L21 -> 3.0903906 | M35: DT1, DT2, HSK3 (if Macro102)
H36: N2, buff rates, N1/N3/Status | I36: =I26+I24+I23+I22+I21 -> 2.642478 | J36: =J26+J24+J23+J22+J21 -> 964.50447 | K36: =K26+K24+K23+K22+K21 -> 30.584236 | L36: =L26+L24+L23+L22+L21 -> 3.8230295 | M36: DT1, DT2, DT3,HSK3
H37: Trig Assess, N2, buff rates, N1/N3/Status | I37: =SUM(I21:I26) -> 2.879178 | J37: =SUM(J21:J26) -> 1050.9 | K37: =SUM(K21:K26) -> 33.323819 | L37: =SUM(L21:L26) -> 4.1654774 | M37: DT1, DT2, DT3, DT4, HSK3
H38: N2 | I38: =I24 -> 0.5064 | J38: =J24 -> 184.836 | K38: =K24 -> 5.8611111 | L38: =L24 -> 0.73263889 | M38: DT3
H39: trig assess | I39: =I25 -> 0.2367 | J39: =J25 -> 86.3955 | K39: =K25 -> 2.7395833 | L39: =L25 -> 0.34244792 | M39: DT4

Sheet hibernation_24267_acq
C3: Load number: | E3: 25139
C4: First | E4: DOY | F4: Hour | G4: Min | H4: Days: | I4: Delta | K4: Burst enabled?
D5: Start: | E5: 0 | F5: 0 | G5: 0 | H5: =E5+(F5+G5/60)/24 -> 0
D6: Stop: | E6: 172 | F6: 0 | G6: 0 | H6: =E6+(F6+G6/60)/24 -> 172 | I6: =H6-H5 -> 172 | K6: yes
C7: Second | O7: The fields in blue need to be updated for each load
D8: Start:
D9: Stop:
C11: How many power-on instances are in this load?: | G11: 1
D13: Settings:
E14: N1 | F14: 180
E15: Macro 103/104? | F15: 103 | G15: --> | H15: N2mon = | I15: =IF(F16=101,3,IF(F15=103,3,2)) -> 3
E16: Macro 105-110? | F16: 101 | H16: macro used= | I16: =IF(F16=101,106, F16) -> 106 | J16: <-- if macro=101, then macro 103/104 field is ignored, and settings for macro 103/106 are automatically used
E17: N3 | F17: 7200
E18: Status | F18: 1800
L19: Science
D20: Telemetry product: | H20: Days | I20: Mbits/day | J20: Total Mbits | K20: bps | L20: bytes/s
E21: N1 | F21: 0x691 | H21: =I$6+I$9 -> 172 | I21: =IF(I15=2,(VLOOKUP($I$16,'Packet size and rates'!G110:AH115, 16,FALSE())), (VLOOKUP($I$16,'Packet size and rates'!G103:AH108, 16,FALSE())))*('Packet size and rates'!V117/F14) -> 0.95424 | J21: =H21*I21 -> 164.12928 | K21: =1000000*I21/(24*3600) -> 11.044444 | L21: =K21/8 -> 1.3805556 | M21: PEPSSI_DT1
E22: N3 | F22: 0x693 | H22: =I$6+I$9 -> 172 | I22: =IF(I15=2,(VLOOKUP($I$16,'Packet size and rates'!G110:AH115, 19,FALSE())), (VLOOKUP($I$16,'Packet size and rates'!G103:AH108, 19,FALSE())))*('Packet size and rates'!Y117/F17) -> 0.218112 | J22: =H22*I22 -> 37.515264 | K22: =1000000*I22/(24*3600) -> 2.5244444 | L22: =K22/8 -> 0.31555556 | M22: PEPSSI_DT2
E23: Status | F23: 0x685 | H23: =I$6+I$9 -> 172 | I23: =IF(I15=2,(VLOOKUP($I$16,'Packet size and rates'!G110:AH115, 13,FALSE())), (VLOOKUP($I$16,'Packet size and rates'!G103:AH108, 13,FALSE())))*('Packet size and rates'!S117/F18) -> 0.024576 | J23: =H23*I23 -> 4.227072 | K23: =1000000*I23/(24*3600) -> 0.28444444 | L23: =K23/8 -> 0.035555556 | M23: INST_HSK_3
E24: N2 | F24: 0x692 | H24: =IF(K$9="yes",I$9,0)+IF(K$6="yes",I$6,0) -> 172 | I24: =IF(I15=2,(VLOOKUP($I$16,'Packet size and rates'!G110:AH115, 25,FALSE())), (VLOOKUP($I$16,'Packet size and rates'!G103:AH108, 25,FALSE()))) -> 0.5064 | J24: =H24*I24 -> 87.1008 | K24: =1000000*I24/(24*3600) -> 5.8611111 | L24: =K24/8 -> 0.73263889 | M24: PEPSSI_DT3
E25: Trigger packet | F25: 0x68A | H25: =IF(K$9="yes",I$9,0)+IF(K$6="yes",I$6,0) -> 172 | I25: =IF(I15=2,(VLOOKUP($I$16,'Packet size and rates'!G110:AH115, 5,FALSE())), (VLOOKUP($I$16,'Packet size and rates'!G103:AH108, 5,FALSE()))) -> 0.2367 | J25: =H25*I25 -> 40.7124 | K25: =1000000*I25/(24*3600) -> 2.7395833 | L25: =K25/8 -> 0.34244792 | M25: PEPSSI_DT4
E26: Buffered Rates | F26: 0x697 | H26: =IF(K$9="yes",I$9,0)+IF(K$6="yes",I$6,0) -> 172 | I26: =IF(I15=2,(VLOOKUP($I$16,'Packet size and rates'!G110:AH115, 8,FALSE())), (VLOOKUP($I$16,'Packet size and rates'!G103:AH108, 8,FALSE()))) -> 0.93915 | J26: =H26*I26 -> 161.5338 | K26: =1000000*I26/(24*3600) -> 10.869792 | L26: =K26/8 -> 1.358724 | M26: DT2 if Mac102, otherwise DT3
E27: SubTotal | I27: =SUM(I21:I26) -> 2.879178 | J27: =SUM(J21:J26) -> 495.21862 | K27: =SUM(K21:K26) -> 33.323819 | L27: =SUM(L21:L26) -> 4.1654774
M28: =M27*86400/1000000 -> 0
E29: Power-on | J29: =1.6*G11 -> 1.6
E31: Total | J31: =J27+J29 -> 496.81862
I33: Mbits/day | J33: Mbits | K33: bps | L33: bytes/s
H34: N1/N3/Status | I34: =I21+I22+I23 -> 1.196928 | J34: =J21+J22+J23 -> 205.87162 | K34: =K21+K22+K23 -> 13.853333 | L34: =L21+L22+L23 -> 1.7316667 | M34: DT1, DT2, HSK3 | N34: Survey
H35: buff rates + N1/N3/Status | I35: =I26+I23+I22+I21 -> 2.136078 | J35: =J26+J23+J22+J21 -> 367.40542 | K35: =K26+K23+K22+K21 -> 24.723125 | L35: =L26+L23+L22+L21 -> 3.0903906 | M35: DT1, DT2, HSK3 (if Macro102) | N35: PEPSSI_DT2 if macro 102
H36: N2, buff rates, N1/N3/Status | I36: =I26+I24+I23+I22+I21 -> 2.642478 | J36: =J26+J24+J23+J22+J21 -> 454.50622 | K36: =K26+K24+K23+K22+K21 -> 30.584236 | L36: =L26+L24+L23+L22+L21 -> 3.8230295 | M36: DT1, DT2, DT3,HSK3
H37: Trig Assess, N2, buff rates, N1/N3/Status | I37: =SUM(I21:I26) -> 2.879178 | J37: =SUM(J21:J26) -> 495.21862 | K37: =SUM(K21:K26) -> 33.323819 | L37: =SUM(L21:L26) -> 4.1654774 | M37: DT1, DT2, DT3, DT4, HSK3
H38: N2 | I38: =I24 -> 0.5064 | J38: =J24 -> 87.1008 | K38: =K24 -> 5.8611111 | L38: =L24 -> 0.73263889 | M38: DT3
H39: trig assess | I39: =I25 -> 0.2367 | J39: =J25 -> 40.7124 | K39: =K25 -> 2.7395833 | L39: =L25 -> 0.34244792 | M39: DT4

Sheet 25096acq
C3: Load number: | E3: 25096
C4: First | E4: DOY | F4: Hour | G4: Min | H4: Days: | I4: Delta | K4: Burst enabled?
D5: Start: | E5: 107 | F5: 0 | G5: 0 | H5: =E5+(F5+G5/60)/24 -> 107
D6: Stop: | E6: 119 | F6: 0 | G6: 0 | H6: =E6+(F6+G6/60)/24 -> 119 | I6: =H6-H5 -> 12 | K6: yes
C7: Second | O7: The fields in blue need to be updated for each load
D8: Start:
D9: Stop:
C11: How many power-on instances are in this load?: | G11: 1
D13: Settings:
E14: N1 | F14: 120
E15: Macro 103/104? | F15: 103 | G15: --> | H15: N2mon = | I15: =IF(F16=101,3,IF(F15=103,3,2)) -> 3
E16: Macro 105-110? | F16: 101 | H16: macro used= | I16: =IF(F16=101,106, F16) -> 106 | J16: <-- if macro=101, then macro 103/104 field is ignored, and settings for macro 103/106 are automatically used
E17: N3 | F17: 7200
E18: Status | F18: 1800 | Q18: Notes:
L19: Science | Q19: For this load 25139, also 25118 and 25096 I actually used 4.8625 based on the numbers
D20: Telemetry product: | H20: Days | I20: Mbits/day | J20: Total Mbits | K20: bps | L20: bytes/s | Q20: in the PDR slides which included Trig Assessment. I did not play those data back, Mops playbacks did.
E21: N1 | F21: 0x691 | H21: =I$6+I$9 -> 12 | I21: =IF(I15=2,(VLOOKUP($I$16,'Packet size and rates'!G110:AH115, 16,FALSE())), (VLOOKUP($I$16,'Packet size and rates'!G103:AH108, 16,FALSE())))*('Packet size and rates'!V117/F14) -> 1.43136 | J21: =H21*I21 -> 17.17632 | K21: =1000000*I21/(24*3600) -> 16.566667 | L21: =K21/8 -> 2.0708333 | M21: PEPSSI_DT1 | Q21: Therefore the science playback tracks will be undersubscribed by ~8%.
E22: N3 | F22: 0x693 | H22: =I$6+I$9 -> 12 | I22: =IF(I15=2,(VLOOKUP($I$16,'Packet size and rates'!G110:AH115, 19,FALSE())), (VLOOKUP($I$16,'Packet size and rates'!G103:AH108, 19,FALSE())))*('Packet size and rates'!Y117/F17) -> 0.218112 | J22: =H22*I22 -> 2.617344 | K22: =1000000*I22/(24*3600) -> 2.5244444 | L22: =K22/8 -> 0.31555556 | M22: PEPSSI_DT2 | Q22: HOWEVER, the Mops playbacks do play back the PEPSSI DT4 and those I believe did not assume the correct rate,
E23: Status | F23: 0x685 | H23: =I$6+I$9 -> 12 | I23: =IF(I15=2,(VLOOKUP($I$16,'Packet size and rates'!G110:AH115, 13,FALSE())), (VLOOKUP($I$16,'Packet size and rates'!G103:AH108, 13,FALSE())))*('Packet size and rates'!S117/F18) -> 0.024576 | J23: =H23*I23 -> 0.294912 | K23: =1000000*I23/(24*3600) -> 0.28444444 | L23: =K23/8 -> 0.035555556 | M23: INST_HSK_3 | Q23: they were likely oversubscribed so it should all work out. I’ll check with Karl.
E24: N2 | F24: 0x692 | H24: =IF(K$9="yes",I$9,0)+IF(K$6="yes",I$6,0) -> 12 | I24: =IF(I15=2,(VLOOKUP($I$16,'Packet size and rates'!G110:AH115, 25,FALSE())), (VLOOKUP($I$16,'Packet size and rates'!G103:AH108, 25,FALSE()))) -> 0.5064 | J24: =H24*I24 -> 6.0768 | K24: =1000000*I24/(24*3600) -> 5.8611111 | L24: =K24/8 -> 0.73263889 | M24: PEPSSI_DT3 | Q24: Hopefully things will be better going forward!
E25: Trigger packet | F25: 0x68A | H25: =IF(K$9="yes",I$9,0)+IF(K$6="yes",I$6,0) -> 12 | I25: =IF(I15=2,(VLOOKUP($I$16,'Packet size and rates'!G110:AH115, 5,FALSE())), (VLOOKUP($I$16,'Packet size and rates'!G103:AH108, 5,FALSE()))) -> 0.2367 | J25: =H25*I25 -> 2.8404 | K25: =1000000*I25/(24*3600) -> 2.7395833 | L25: =K25/8 -> 0.34244792 | M25: PEPSSI_DT4
E26: Buffered Rates | F26: 0x697 | H26: =IF(K$9="yes",I$9,0)+IF(K$6="yes",I$6,0) -> 12 | I26: =IF(I15=2,(VLOOKUP($I$16,'Packet size and rates'!G110:AH115, 8,FALSE())), (VLOOKUP($I$16,'Packet size and rates'!G103:AH108, 8,FALSE()))) -> 0.93915 | J26: =H26*I26 -> 11.2698 | K26: =1000000*I26/(24*3600) -> 10.869792 | L26: =K26/8 -> 1.358724 | M26: DT2 if Mac102, otherwise DT3
E27: SubTotal | I27: =SUM(I21:I26) -> 3.356298 | J27: =SUM(J21:J26) -> 40.275576 | K27: =SUM(K21:K26) -> 38.846042 | L27: =SUM(L21:L26) -> 4.8557552
E29: Power-on | J29: =1.6*G11 -> 1.6
E31: Total | J31: =J27+J29 -> 41.875576
I33: Mbits/day | J33: Mbits | K33: bps | L33: bytes/s
H34: N1/N3/Status | I34: =I21+I22+I23 -> 1.674048 | J34: =J21+J22+J23 -> 20.088576 | K34: =K21+K22+K23 -> 19.375556 | L34: =L21+L22+L23 -> 2.4219444 | M34: DT1, DT2, HSK3 | N34: Survey
H35: buff rates + N1/N3/Status | I35: =I26+I23+I22+I21 -> 2.613198 | J35: =J26+J23+J22+J21 -> 31.358376 | K35: =K26+K23+K22+K21 -> 30.245347 | L35: =L26+L23+L22+L21 -> 3.7806684 | M35: DT1, DT2, HSK3 (if Macro102) | N35: PEPSSI_DT2 if macro 102
H36: N2, buff rates, N1/N3/Status | I36: =I26+I24+I23+I22+I21 -> 3.119598 | J36: =J26+J24+J23+J22+J21 -> 37.435176 | K36: =K26+K24+K23+K22+K21 -> 36.106458 | L36: =L26+L24+L23+L22+L21 -> 4.5133073 | M36: DT1, DT2, DT3,HSK3
H37: Trig Assess, N2, buff rates, N1/N3/Status | I37: =SUM(I21:I26) -> 3.356298 | J37: =SUM(J21:J26) -> 40.275576 | K37: =SUM(K21:K26) -> 38.846042 | L37: =SUM(L21:L26) -> 4.8557552 | M37: DT1, DT2, DT3, DT4, HSK3
H38: N2 | I38: =I24 -> 0.5064 | J38: =J24 -> 6.0768 | K38: =K24 -> 5.8611111 | L38: =L24 -> 0.73263889 | M38: DT3
H39: trig assess | I39: =I25 -> 0.2367 | J39: =J25 -> 2.8404 | K39: =K25 -> 2.7395833 | L39: =L25 -> 0.34244792 | M39: DT4

Sheet 25118
C3: Load number: | E3: 25118
C4: First | E4: DOY | F4: Hour | G4: Min | H4: Days: | I4: Delta | K4: Burst enabled?
D5: Start: | E5: 119 | F5: 0 | G5: 0 | H5: =E5+(F5+G5/60)/24 -> 119 | M5: 135 | N5: 0 | O5: 0
D6: Stop: | E6: 160 | F6: 0 | G6: 0 | H6: =E6+(F6+G6/60)/24 -> 160 | I6: =H6-H5 -> 41 | K6: yes | M6: 160 | N6: 0 | O6: 0
C7: Second | O7: The fields in blue need to be updated for each load
D8: Start:
D9: Stop:
C11: How many power-on instances are in this load?: | G11: 1
D13: Settings:
E14: N1 | F14: 120
E15: Macro 103/104? | F15: 103 | G15: --> | H15: N2mon = | I15: =IF(F16=101,3,IF(F15=103,3,2)) -> 3
E16: Macro 105-110? | F16: 101 | H16: macro used= | I16: =IF(F16=101,106, F16) -> 106 | J16: <-- if macro=101, then macro 103/104 field is ignored, and settings for macro 103/106 are automatically used
E17: N3 | F17: 7200
E18: Status | F18: 1800
L19: Science
D20: Telemetry product: | H20: Days | I20: Mbits/day | J20: Total Mbits | K20: bps | L20: bytes/s
E21: N1 | F21: 0x691 | H21: =I$6+I$9 -> 41 | I21: =IF(I15=2,(VLOOKUP($I$16,'Packet size and rates'!G110:AH115, 16,FALSE())), (VLOOKUP($I$16,'Packet size and rates'!G103:AH108, 16,FALSE())))*('Packet size and rates'!V117/F14) -> 1.43136 | J21: =H21*I21 -> 58.68576 | K21: =1000000*I21/(24*3600) -> 16.566667 | L21: =K21/8 -> 2.0708333 | M21: PEPSSI_DT1
E22: N3 | F22: 0x693 | H22: =I$6+I$9 -> 41 | I22: =IF(I15=2,(VLOOKUP($I$16,'Packet size and rates'!G110:AH115, 19,FALSE())), (VLOOKUP($I$16,'Packet size and rates'!G103:AH108, 19,FALSE())))*('Packet size and rates'!Y117/F17) -> 0.218112 | J22: =H22*I22 -> 8.942592 | K22: =1000000*I22/(24*3600) -> 2.5244444 | L22: =K22/8 -> 0.31555556 | M22: PEPSSI_DT2
E23: Status | F23: 0x685 | H23: =I$6+I$9 -> 41 | I23: =IF(I15=2,(VLOOKUP($I$16,'Packet size and rates'!G110:AH115, 13,FALSE())), (VLOOKUP($I$16,'Packet size and rates'!G103:AH108, 13,FALSE())))*('Packet size and rates'!S117/F18) -> 0.024576 | J23: =H23*I23 -> 1.007616 | K23: =1000000*I23/(24*3600) -> 0.28444444 | L23: =K23/8 -> 0.035555556 | M23: INST_HSK_3
E24: N2 | F24: 0x692 | H24: =IF(K$9="yes",I$9,0)+IF(K$6="yes",I$6,0) -> 41 | I24: =IF(I15=2,(VLOOKUP($I$16,'Packet size and rates'!G110:AH115, 25,FALSE())), (VLOOKUP($I$16,'Packet size and rates'!G103:AH108, 25,FALSE()))) -> 0.5064 | J24: =H24*I24 -> 20.7624 | K24: =1000000*I24/(24*3600) -> 5.8611111 | L24: =K24/8 -> 0.73263889 | M24: PEPSSI_DT3
E25: Trigger packet | F25: 0x68A | H25: =IF(K$9="yes",I$9,0)+IF(K$6="yes",I$6,0) -> 41 | I25: =IF(I15=2,(VLOOKUP($I$16,'Packet size and rates'!G110:AH115, 5,FALSE())), (VLOOKUP($I$16,'Packet size and rates'!G103:AH108, 5,FALSE()))) -> 0.2367 | J25: =H25*I25 -> 9.7047 | K25: =1000000*I25/(24*3600) -> 2.7395833 | L25: =K25/8 -> 0.34244792 | M25: PEPSSI_DT4
E26: Buffered Rates | F26: 0x697 | H26: =IF(K$9="yes",I$9,0)+IF(K$6="yes",I$6,0) -> 41 | I26: =IF(I15=2,(VLOOKUP($I$16,'Packet size and rates'!G110:AH115, 8,FALSE())), (VLOOKUP($I$16,'Packet size and rates'!G103:AH108, 8,FALSE()))) -> 0.93915 | J26: =H26*I26 -> 38.50515 | K26: =1000000*I26/(24*3600) -> 10.869792 | L26: =K26/8 -> 1.358724 | M26: DT2 if Mac102, otherwise DT3
E27: SubTotal | I27: =SUM(I21:I26) -> 3.356298 | J27: =SUM(J21:J26) -> 137.60822 | K27: =SUM(K21:K26) -> 38.846042 | L27: =SUM(L21:L26) -> 4.8557552
E29: Power-on | J29: =1.6*G11 -> 1.6
E31: Total | J31: =J27+J29 -> 139.20822
I33: Mbits/day | J33: Mbits | K33: bps | L33: bytes/s
H34: N1/N3/Status | I34: =I21+I22+I23 -> 1.674048 | J34: =J21+J22+J23 -> 68.635968 | K34: =K21+K22+K23 -> 19.375556 | L34: =L21+L22+L23 -> 2.4219444 | M34: DT1, DT2, HSK3 | N34: Survey
H35: buff rates + N1/N3/Status | I35: =I26+I23+I22+I21 -> 2.613198 | J35: =J26+J23+J22+J21 -> 107.14112 | K35: =K26+K23+K22+K21 -> 30.245347 | L35: =L26+L23+L22+L21 -> 3.7806684 | M35: DT1, DT2, HSK3 (if Macro102) | N35: PEPSSI_DT2 if macro 102
H36: N2, buff rates, N1/N3/Status | I36: =I26+I24+I23+I22+I21 -> 3.119598 | J36: =J26+J24+J23+J22+J21 -> 127.90352 | K36: =K26+K24+K23+K22+K21 -> 36.106458 | L36: =L26+L24+L23+L22+L21 -> 4.5133073 | M36: DT1, DT2, DT3,HSK3
H37: Trig Assess, N2, buff rates, N1/N3/Status | I37: =SUM(I21:I26) -> 3.356298 | J37: =SUM(J21:J26) -> 137.60822 | K37: =SUM(K21:K26) -> 38.846042 | L37: =SUM(L21:L26) -> 4.8557552 | M37: DT1, DT2, DT3, DT4, HSK3
H38: N2 | I38: =I24 -> 0.5064 | J38: =J24 -> 20.7624 | K38: =K24 -> 5.8611111 | L38: =L24 -> 0.73263889 | M38: DT3
H39: trig assess | I39: =I25 -> 0.2367 | J39: =J25 -> 9.7047 | K39: =K25 -> 2.7395833 | L39: =L25 -> 0.34244792 | M39: DT4

Sheet 25139
C3: Load number: | E3: 25139
C4: First | E4: DOY | F4: Hour | G4: Min | H4: Days: | I4: Delta | K4: Burst enabled?
D5: Start: | E5: 135 | F5: 13 | G5: 16 | H5: =E5+(F5+G5/60)/24 -> 135.55278
D6: Stop: | E6: 160 | F6: 3 | G6: 2 | H6: =E6+(F6+G6/60)/24 -> 160.12639 | I6: =H6-H5 -> 24.573611 | K6: yes
C7: Second | O7: The fields in blue need to be updated for each load
D8: Start:
D9: Stop:
C11: How many power-on instances are in this load?: | G11: 1
D13: Settings:
E14: N1 | F14: 120
E15: Macro 103/104? | F15: 103 | G15: --> | H15: N2mon = | I15: =IF(F16=101,3,IF(F15=103,3,2)) -> 3
E16: Macro 105-110? | F16: 101 | H16: macro used= | I16: =IF(F16=101,106, F16) -> 106 | J16: <-- if macro=101, then macro 103/104 field is ignored, and settings for macro 103/106 are automatically used
E17: N3 | F17: 7200
E18: Status | F18: 1800
L19: Science
D20: Telemetry product: | H20: Days | I20: Mbits/day | J20: Total Mbits | K20: bps | L20: bytes/s
E21: N1 | F21: 0x691 | H21: =I$6+I$9 -> 24.573611 | I21: =IF(I15=2,(VLOOKUP($I$16,'Packet size and rates'!G110:AH115, 16,FALSE())), (VLOOKUP($I$16,'Packet size and rates'!G103:AH108, 16,FALSE())))*('Packet size and rates'!V117/F14) -> 1.43136 | J21: =H21*I21 -> 35.173684 | K21: =1000000*I21/(24*3600) -> 16.566667 | L21: =K21/8 -> 2.0708333 | M21: PEPSSI_DT1 | P21: 16.566667
E22: N3 | F22: 0x693 | H22: =I$6+I$9 -> 24.573611 | I22: =IF(I15=2,(VLOOKUP($I$16,'Packet size and rates'!G110:AH115, 19,FALSE())), (VLOOKUP($I$16,'Packet size and rates'!G103:AH108, 19,FALSE())))*('Packet size and rates'!Y117/F17) -> 0.218112 | J22: =H22*I22 -> 5.3597995 | K22: =1000000*I22/(24*3600) -> 2.5244444 | L22: =K22/8 -> 0.31555556 | M22: PEPSSI_DT2 | P22: 2.5244444
E23: Status | F23: 0x685 | H23: =I$6+I$9 -> 24.573611 | I23: =IF(I15=2,(VLOOKUP($I$16,'Packet size and rates'!G110:AH115, 13,FALSE())), (VLOOKUP($I$16,'Packet size and rates'!G103:AH108, 13,FALSE())))*('Packet size and rates'!S117/F18) -> 0.024576 | J23: =H23*I23 -> 0.60392107 | K23: =1000000*I23/(24*3600) -> 0.28444444 | L23: =K23/8 -> 0.035555556 | M23: INST_HSK_3 | P23: 0.28444444
E24: N2 | F24: 0x692 | H24: =IF(K$9="yes",I$9,0)+IF(K$6="yes",I$6,0) -> 24.573611 | I24: =IF(I15=2,(VLOOKUP($I$16,'Packet size and rates'!G110:AH115, 25,FALSE())), (VLOOKUP($I$16,'Packet size and rates'!G103:AH108, 25,FALSE()))) -> 0.5064 | J24: =H24*I24 -> 12.444077 | K24: =1000000*I24/(24*3600) -> 5.8611111 | L24: =K24/8 -> 0.73263889 | M24: PEPSSI_DT3 | P24: 5.8611111
E25: Trigger packet | F25: 0x68A | H25: =IF(K$9="yes",I$9,0)+IF(K$6="yes",I$6,0) -> 24.573611 | I25: =IF(I15=2,(VLOOKUP($I$16,'Packet size and rates'!G110:AH115, 5,FALSE())), (VLOOKUP($I$16,'Packet size and rates'!G103:AH108, 5,FALSE()))) -> 0.2367 | J25: =H25*I25 -> 5.8165738 | K25: =1000000*I25/(24*3600) -> 2.7395833 | L25: =K25/8 -> 0.34244792 | M25: PEPSSI_DT4 | P25: 2.7395833
E26: Buffered Rates | F26: 0x697 | H26: =IF(K$9="yes",I$9,0)+IF(K$6="yes",I$6,0) -> 24.573611 | I26: =IF(I15=2,(VLOOKUP($I$16,'Packet size and rates'!G110:AH115, 8,FALSE())), (VLOOKUP($I$16,'Packet size and rates'!G103:AH108, 8,FALSE()))) -> 0.93915 | J26: =H26*I26 -> 23.078307 | K26: =1000000*I26/(24*3600) -> 10.869792 | L26: =K26/8 -> 1.358724 | M26: DT2 if Mac102, otherwise DT3 | P26: 10.869792
E27: SubTotal | I27: =SUM(I21:I26) -> 3.356298 | J27: =SUM(J21:J26) -> 82.476362 | K27: =SUM(K21:K26) -> 38.846042 | L27: =SUM(L21:L26) -> 4.8557552
E29: Power-on | J29: =1.6*G11 -> 1.6
E31: Total | J31: =J27+J29 -> 84.076362
I33: Mbits/day | J33: Mbits | K33: bps | L33: bytes/s
H34: N1/N3/Status | I34: =I21+I22+I23 -> 1.674048 | J34: =J21+J22+J23 -> 41.137405 | K34: =K21+K22+K23 -> 19.375556 | L34: =L21+L22+L23 -> 2.4219444 | M34: DT1, DT2, HSK3 | N34: Survey
H35: buff rates + N1/N3/Status | I35: =I26+I23+I22+I21 -> 2.613198 | J35: =J26+J23+J22+J21 -> 64.215711 | K35: =K26+K23+K22+K21 -> 30.245347 | L35: =L26+L23+L22+L21 -> 3.7806684 | M35: DT1, DT2, HSK3 (if Macro102) | N35: PEPSSI_DT2 if macro 102
H36: N2, buff rates, N1/N3/Status | I36: =I26+I24+I23+I22+I21 -> 3.119598 | J36: =J26+J24+J23+J22+J21 -> 76.659788 | K36: =K26+K24+K23+K22+K21 -> 36.106458 | L36: =L26+L24+L23+L22+L21 -> 4.5133073 | M36: DT1, DT2, DT3,HSK3
H37: Trig Assess, N2, buff rates, N1/N3/Status | I37: =SUM(I21:I26) -> 3.356298 | J37: =SUM(J21:J26) -> 82.476362 | K37: =SUM(K21:K26) -> 38.846042 | L37: =SUM(L21:L26) -> 4.8557552 | M37: DT1, DT2, DT3, DT4, HSK3
H38: N2 | I38: =I24 -> 0.5064 | J38: =J24 -> 12.444077 | K38: =K24 -> 5.8611111 | L38: =L24 -> 0.73263889 | M38: DT3
H39: trig assess | I39: =I25 -> 0.2367 | J39: =J25 -> 5.8165738 | K39: =K25 -> 2.7395833 | L39: =L25 -> 0.34244792 | M39: DT4

Sheet 25159
N2: 160 | O2: 3 | P2: 11
C3: Load number: | E3: 25159 | N3: 178 | O3: 19 | P3: 30
C4: First | E4: DOY | F4: Hour | G4: Min | H4: Days: | I4: Delta | K4: Burst enabled?
D5: Start: | E5: 160 | F5: 3 | G5: 11 | H5: =E5+(F5+G5/60)/24 -> 160.13264
D6: Stop: | E6: 178 | F6: 19 | G6: 30 | H6: =E6+(F6+G6/60)/24 -> 178.8125 | I6: =H6-H5 -> 18.679861 | K6: yes
C7: Second | O7: The fields in blue need to be updated for each load
D8: Start: | E8: 178 | F8: 19 | G8: 30 | H8: =E8+(F8+G8/60)/24 -> 178.8125
D9: Stop: | E9: 181 | F9: 2 | G9: 10 | H9: =E9+(F9+G9/60)/24 -> 181.09028 | I9: =H9-H8 -> 2.2777778 | K9: yes
C11: How many power-on instances are in this load?: | G11: 1
D13: Settings:
E14: N1 | F14: 180
E15: Macro 103/104? | F15: 103 | G15: --> | H15: N2mon = | I15: =IF(F16=101,3,IF(F15=103,3,2)) -> 3
E16: Macro 105-110? | F16: 110 | H16: macro used= | I16: =IF(F16=101,106, F16) -> 110 | J16: <-- if macro=101, then macro 103/104 field is ignored, and settings for macro 103/106 are automatically used
E17: N3 | F17: 7200
E18: Status | F18: 1800
L19: Science
D20: Telemetry product: | H20: Days | I20: Mbits/day | J20: Total Mbits | K20: bps | L20: bytes/s
E21: N1 | F21: 0x691 | H21: =I$6+I$9 -> 20.957639 | I21: =IF(I15=2,(VLOOKUP($I$16,'Packet size and rates'!G110:AH115, 16,FALSE())), (VLOOKUP($I$16,'Packet size and rates'!G103:AH108, 16,FALSE())))*('Packet size and rates'!V117/F14) -> 0.95424 | J21: =H21*I21 -> 19.998617 | K21: =1000000*I21/(24*3600) -> 11.044444 | L21: =K21/8 -> 1.3805556 | M21: PEPSSI_DT1 | P21: 11.044444
E22: N3 | F22: 0x693 | H22: =I$6+I$9 -> 20.957639 | I22: =IF(I15=2,(VLOOKUP($I$16,'Packet size and rates'!G110:AH115, 19,FALSE())), (VLOOKUP($I$16,'Packet size and rates'!G103:AH108, 19,FALSE())))*('Packet size and rates'!Y117/F17) -> 0.218112 | J22: =H22*I22 -> 4.5711125 | K22: =1000000*I22/(24*3600) -> 2.5244444 | L22: =K22/8 -> 0.31555556 | M22: PEPSSI_DT2 | P22: 2.5244444
E23: Status | F23: 0x685 | H23: =I$6+I$9 -> 20.957639 | I23: =IF(I15=2,(VLOOKUP($I$16,'Packet size and rates'!G110:AH115, 13,FALSE())), (VLOOKUP($I$16,'Packet size and rates'!G103:AH108, 13,FALSE())))*('Packet size and rates'!S117/F18) -> 0.024576 | J23: =H23*I23 -> 0.51505493 | K23: =1000000*I23/(24*3600) -> 0.28444444 | L23: =K23/8 -> 0.035555556 | M23: INST_HSK_3 | P23: 0.28444444
E24: N2 | F24: 0x692 | H24: =IF(K$9="yes",I$9,0)+IF(K$6="yes",I$6,0) -> 20.957639 | I24: =IF(I15=2,(VLOOKUP($I$16,'Packet size and rates'!G110:AH115, 25,FALSE())), (VLOOKUP($I$16,'Packet size and rates'!G103:AH108, 25,FALSE()))) -> 36.4608 | J24: =H24*I24 -> 764.13228 | K24: =1000000*I24/(24*3600) -> 422 | L24: =K24/8 -> 52.75 | M24: PEPSSI_DT3 | P24: 422
E25: Trigger packet | F25: 0x68A | H25: =IF(K$9="yes",I$9,0)+IF(K$6="yes",I$6,0) -> 20.957639 | I25: =IF(I15=2,(VLOOKUP($I$16,'Packet size and rates'!G110:AH115, 5,FALSE())), (VLOOKUP($I$16,'Packet size and rates'!G103:AH108, 5,FALSE()))) -> 0.2367 | J25: =H25*I25 -> 4.9606731 | K25: =1000000*I25/(24*3600) -> 2.7395833 | L25: =K25/8 -> 0.34244792 | M25: PEPSSI_DT4 | P25: 2.7395833
E26: Buffered Rates | F26: 0x697 | H26: =IF(K$9="yes",I$9,0)+IF(K$6="yes",I$6,0) -> 20.957639 | I26: =IF(I15=2,(VLOOKUP($I$16,'Packet size and rates'!G110:AH115, 8,FALSE())), (VLOOKUP($I$16,'Packet size and rates'!G103:AH108, 8,FALSE()))) -> 0.93915 | J26: =H26*I26 -> 19.682367 | K26: =1000000*I26/(24*3600) -> 10.869792 | L26: =K26/8 -> 1.358724 | M26: DT2 if Mac102, otherwise DT3 | P26: 10.869792
E27: SubTotal | I27: =SUM(I21:I26) -> 38.833578 | J27: =SUM(J21:J26) -> 813.8601 | K27: =SUM(K21:K26) -> 449.46271 | L27: =SUM(L21:L26) -> 56.182839
E29: Power-on | J29: 1.6
E31: Total | J31: =J27+J29 -> 815.4601
I33: Mbits/day | J33: Mbits | K33: bps | L33: bytes/s | S33: 64.22 | T33: 25139 | U33: 135-160
H34: N1/N3/Status | I34: =I21+I22+I23 -> 1.196928 | J34: =J21+J22+J23 -> 25.084785 | K34: =K21+K22+K23 -> 13.853333 | L34: =L21+L22+L23 -> 1.7316667 | M34: DT1, DT2, HSK3 | O34: Survey | S34: 39.9 | T34: 25159 | U34: 160-178
H35: buff rates + N1/N3/Status | I35: =I26+I23+I22+I21 -> 2.136078 | J35: =J26+J23+J22+J21 -> 44.767151 | K35: =K26+K23+K22+K21 -> 24.723125 | L35: =L26+L23+L22+L21 -> 3.0903906 | M35: DT1, DT2, HSK3 (if Macro102) | N35: PEPSSI_DT2 if macro 102 | S35: =64.22+39.9 -> 104.12 | T35: yes! | U35: 178/1930-181/0210
H36: N2, buff rates, N1/N3/Status | I36: =I26+I24+I23+I22+I21 -> 38.596878 | J36: =J26+J24+J23+J22+J21 -> 808.89943 | K36: =K26+K24+K23+K22+K21 -> 446.72312 | L36: =L26+L24+L23+L22+L21 -> 55.840391 | M36: DT1, DT2, DT3,HSK3
H37: Trig Assess, N2, buff rates, N1/N3/Status | I37: =SUM(I21:I26) -> 38.833578 | J37: =SUM(J21:J26) -> 813.8601 | K37: =SUM(K21:K26) -> 449.46271 | L37: =SUM(L21:L26) -> 56.182839 | M37: DT1, DT2, DT3, DT4, HSK3
H38: N2 | I38: =I24 -> 36.4608 | J38: =J24 -> 764.13228 | K38: =K24 -> 422 | L38: =L24 -> 52.75 | M38: DT3 | S38: 4.87 | U38: 178-181 | V38: survey+br
H39: trig assess | I39: =I25 -> 0.2367 | J39: =J25 -> 4.9606731 | K39: =K25 -> 2.7395833 | L39: =L25 -> 0.34244792 | M39: DT4
H40: Trig Assess, buff rates | I40: =I26+I25 -> 1.17585 | J40: =J26+J25 -> 24.64304 | K40: =K26+K25 -> 13.609375 | L40: =L26+L25 -> 1.7011719 | M40: DT1, DT2, DT3, DT4, HSK3
H41: N1, N2, Status, Trig Assess | I41: =I21+I23+I24+I25 -> 37.676316 | J41: =J21+J23+J24+J25 -> 789.60663 | K41: =K21+K23+K24+K25 -> 436.06847 | L41: =L21+L23+L24+L25 -> 54.508559 | M41: DT1, DT3, DT4, HSK3
H42: N1, Status, Trig Assess | I42: =I22+I25+I26 -> 1.393962 | J42: =J22+J25+J26 -> 29.214152 | K42: =K22+K25+K26 -> 16.133819 | L42: =L22+L25+L26 -> 2.0167274 | M42: DT1, DT4, HSK3

Sheet 25181
N2: 188 | O2: 5 | P2: 28
C3: Load number: | E3: 25181 | N3: 202 | O3: 2 | P3: 6
C4: First | E4: DOY | F4: Hour | G4: Min | H4: Days: | I4: Delta | K4: Burst enabled?
D5: Start: | E5: 181 | F5: 3 | G5: 15 | H5: =E5+(F5+G5/60)/24 -> 181.13542 | N5: 181 | O5: 3 | P5: 10
D6: Stop: | E6: 201 | F6: 17 | G6: 35 | H6: =E6+(F6+G6/60)/24 -> 201.73264 | I6: =H6-H5 -> 20.597222 | K6: yes | N6: 201 | O6: 17 | P6: 35
C7: Second | O7: The fields in blue need to be updated for each load
D8: Start: | E8: 206 | F8: 20 | G8: 15 | H8: =E8+(F8+G8/60)/24 -> 206.84375 | N8: 206 | O8: 20 | P8: 15
D9: Stop: | E9: 207 | F9: 17 | G9: 23 | H9: =E9+(F9+G9/60)/24 -> 207.72431 | I9: =H9-H8 -> 0.88055556 | K9: no | N9: 207 | O9: 0 | P9: 0
C11: How many power-on instances are in this load?: | G11: 1
D13: Settings:
E14: N1 | F14: 180
E15: Macro 103/104? | F15: 103 | G15: --> | H15: N2mon = | I15: =IF(F16=101,3,IF(F15=103,3,2)) -> 3
E16: Macro 105-110? | F16: 105 | H16: macro used= | I16: =IF(F16=101,106, F16) -> 105 | J16: <-- if macro=101, then macro 103/104 field is ignored, and settings for macro 103/106 are automatically used
E17: N3 | F17: 7200
E18: Status | F18: 1800
L19: Science
D20: Telemetry product: | H20: Days | I20: Mbits/day | J20: Total Mbits | K20: bps | L20: bytes/s
E21: N1 | F21: 0x691 | H21: =I$6+I$9 -> 21.477778 | I21: =IF(I15=2,(VLOOKUP($I$16,'Packet size and rates'!G110:AH115, 16,FALSE())), (VLOOKUP($I$16,'Packet size and rates'!G103:AH108, 16,FALSE())))*('Packet size and rates'!V117/F14) -> 0.95424 | J21: =H21*I21 -> 20.494955 | K21: =1000000*I21/(24*3600) -> 11.044444 | L21: =K21/8 -> 1.3805556 | M21: PEPSSI_DT1 | P21: 11.044444 | Q21: 1.3805556
E22: N3 | F22: 0x693 | H22: =I$6+I$9 -> 21.477778 | I22: =IF(I15=2,(VLOOKUP($I$16,'Packet size and rates'!G110:AH115, 19,FALSE())), (VLOOKUP($I$16,'Packet size and rates'!G103:AH108, 19,FALSE())))*('Packet size and rates'!Y117/F17) -> 0.218112 | J22: =H22*I22 -> 4.6845611 | K22: =1000000*I22/(24*3600) -> 2.5244444 | L22: =K22/8 -> 0.31555556 | M22: PEPSSI_DT2 | P22: 2.5244444 | Q22: 0.31555556
E23: Status | F23: 0x685 | H23: =I$6+I$9 -> 21.477778 | I23: =IF(I15=2,(VLOOKUP($I$16,'Packet size and rates'!G110:AH115, 13,FALSE())), (VLOOKUP($I$16,'Packet size and rates'!G103:AH108, 13,FALSE())))*('Packet size and rates'!S117/F18) -> 0.024576 | J23: =H23*I23 -> 0.52783787 | K23: =1000000*I23/(24*3600) -> 0.28444444 | L23: =K23/8 -> 0.035555556 | M23: INST_HSK_3 | P23: 0.28444444 | Q23: 0.035555556
E24: N2 | F24: 0x692 | H24: =IF(K$9="yes",I$9,0)+IF(K$6="yes",I$6,0) -> 20.597222 | I24: =IF(I15=2,(VLOOKUP($I$16,'Packet size and rates'!G110:AH115, 25,FALSE())), (VLOOKUP($I$16,'Packet size and rates'!G103:AH108, 25,FALSE()))) -> 0.2532 | J24: =H24*I24 -> 5.2152167 | K24: =1000000*I24/(24*3600) -> 2.9305556 | L24: =K24/8 -> 0.36631944 | M24: PEPSSI_DT3 | P24: 2.9305556 | Q24: 0.36631944
E25: Trigger packet | F25: 0x68A | H25: =IF(K$9="yes",I$9,0)+IF(K$6="yes",I$6,0) -> 20.597222 | I25: =IF(I15=2,(VLOOKUP($I$16,'Packet size and rates'!G110:AH115, 5,FALSE())), (VLOOKUP($I$16,'Packet size and rates'!G103:AH108, 5,FALSE()))) -> 0.2367 | J25: =H25*I25 -> 4.8753625 | K25: =1000000*I25/(24*3600) -> 2.7395833 | L25: =K25/8 -> 0.34244792 | M25: PEPSSI_DT4 | P25: 2.7395833 | Q25: 0.34244792
E26: Buffered Rates | F26: 0x697 | H26: =IF(K$9="yes",I$9,0)+IF(K$6="yes",I$6,0) -> 20.597222 | I26: =IF(I15=2,(VLOOKUP($I$16,'Packet size and rates'!G110:AH115, 8,FALSE())), (VLOOKUP($I$16,'Packet size and rates'!G103:AH108, 8,FALSE()))) -> 0.93915 | J26: =H26*I26 -> 19.343881 | K26: =1000000*I26/(24*3600) -> 10.869792 | L26: =K26/8 -> 1.358724 | M26: DT2 if Mac102, otherwise DT3 | P26: 10.869792 | Q26: 1.358724
E27: SubTotal | I27: =SUM(I21:I26) -> 2.625978 | J27: =SUM(J21:J26) -> 55.141814 | K27: =SUM(K21:K26) -> 30.393264 | L27: =SUM(L21:L26) -> 3.799158
E29: Power-on | J29: =1.6*G11 -> 1.6
E31: Total | J31: =J27+J29 -> 56.741814
I33: Mbits/day | J33: Mbits | K33: bps | L33: bytes/s
H34: N1/N3/Status | I34: =I21+I22+I23 -> 1.196928 | J34: =J21+J22+J23 -> 25.707354 | K34: =K21+K22+K23 -> 13.853333 | L34: =L21+L22+L23 -> 1.7316667 | M34: DT1, DT2, HSK3 | N34: Survey
H35: buff rates + N1/N3/Status | I35: =I26+I23+I22+I21 -> 2.136078 | J35: =J26+J23+J22+J21 -> 45.051235 | K35: =K26+K23+K22+K21 -> 24.723125 | L35: =L26+L23+L22+L21 -> 3.0903906 | M35: DT1, DT2, HSK3 (if Macro102) | N35: PEPSSI_DT2 if macro 102 | R35: 181-201 | S35: 44 | T35: surv+br
H36: N2, buff rates, N1/N3/Status | I36: =I26+I24+I23+I22+I21 -> 2.389278 | J36: =J26+J24+J23+J22+J21 -> 50.266452 | K36: =K26+K24+K23+K22+K21 -> 27.653681 | L36: =L26+L24+L23+L22+L21 -> 3.4567101 | M36: DT1, DT2, DT3,HSK3 | R36: 206-207 | S36: 0.2 | T36: surv only
H37: Trig Assess, N2, buff rates, N1/N3/Status | I37: =SUM(I21:I26) -> 2.625978 | J37: =SUM(J21:J26) -> 55.141814 | K37: =SUM(K21:K26) -> 30.393264 | L37: =SUM(L21:L26) -> 3.799158 | M37: DT1, DT2, DT3, DT4, HSK3
H38: N2 | I38: =I24 -> 0.2532 | J38: =J24 -> 5.2152167 | K38: =K24 -> 2.9305556 | L38: =L24 -> 0.36631944 | M38: DT3
H39: trig assess | I39: =I25 -> 0.2367 | J39: =J25 -> 4.8753625 | K39: =K25 -> 2.7395833 | L39: =L25 -> 0.34244792 | M39: DT4
H40: Trig Assess, buff rates | I40: =I26+I25 -> 1.17585 | J40: =J26+J25 -> 24.219244 | K40: =K26+K25 -> 13.609375 | L40: =L26+L25 -> 1.7011719 | M40: DT1, DT2, DT3, DT4, HSK3
H41: N1, N2, Status, Trig Assess | I41: =I21+I23+I24+I25 -> 1.468716 | J41: =J21+J23+J24+J25 -> 31.113372 | K41: =K21+K23+K24+K25 -> 16.999028 | L41: =L21+L23+L24+L25 -> 2.1248785 | M41: DT1, DT3, DT4, HSK3
H42: N1, Status, Trig Assess | I42: =I22+I25+I26 -> 1.393962 | J42: =J22+J25+J26 -> 28.903805 | K42: =K22+K25+K26 -> 16.133819 | L42: =L22+L25+L26 -> 2.0167274 | M42: DT1, DT4, HSK3
H43: N3, buff rates | I43: =I26+I22 -> 1.157262 | J43: =J26+J22 -> 24.028442 | K43: =K26+K22 -> 13.394236 | L43: =L26+L22 -> 1.6742795 | M43: DT2 with macro 102

Sheet 25207
C3: Load number: | E3: 25207
C4: First | E4: DOY | F4: Hour | G4: Min | H4: Days: | I4: Delta | K4: Burst enabled?
D5: Start: | E5: 217 | F5: 17 | G5: 24 | H5: =E5+(F5+G5/60)/24 -> 217.725
D6: Stop: | E6: 218 | F6: 17 | G6: 27 | H6: =E6+(F6+G6/60)/24 -> 218.72708 | I6: =H6-H5 -> 1.0020833 | K6: yes
C7: Second | O7: The fields in blue need to be updated for each load
D8: Start: | H8: =E8+(F8+G8/60)/24 -> 0 | M8: 219 | N8: 3 | O8: 27
D9: Stop: | H9: =E9+(F9+G9/60)/24 -> 0 | I9: =H9-H8 -> 0 | K9: yes | M9: =219+365-219+165 -> 530 | N9: 23 | O9: 0
E10: =365-219 -> 146 | F10: 165 | G10: =219+F10+E10 -> 530
C11: How many power-on instances are in this load?: | G11: 1
D13: Settings:
E14: N1 | F14: 360
E15: Macro 103/104? | F15: 104 | G15: --> | H15: N2mon = | I15: =IF(F16=101,3,IF(F15=103,3,2)) -> 2
E16: Macro 105-110? | F16: 105 | H16: macro used= | I16: =IF(F16=101,106, F16) -> 105 | J16: <-- if macro=101, then macro 103/104 field is ignored, and settings for macro 103/106 are automatically used
E17: N3 | F17: 900
E18: Status | F18: 1800
L19: Science
D20: Telemetry product: | H20: Days | I20: Mbits/day | J20: Total Mbits | K20: bps | L20: bytes/s
E21: N1 | F21: 0x691 | H21: =I$6+I$9 -> 1.0020833 | I21: =IF(I15=2,(VLOOKUP($I$16,'Packet size and rates'!G110:AH115, 16,FALSE())), (VLOOKUP($I$16,'Packet size and rates'!G103:AH108, 16,FALSE())))*('Packet size and rates'!V117/F14) -> 0.47712 | J21: =H21*I21 -> 0.478114 | K21: =1000000*I21/(24*3600) -> 5.5222222 | L21: =K21/8 -> 0.69027778 | M21: PEPSSI_DT1 | P21: `
E22: N3 | F22: 0x693 | H22: =I$6+I$9 -> 1.0020833 | I22: =IF(I15=2,(VLOOKUP($I$16,'Packet size and rates'!G110:AH115, 19,FALSE())), (VLOOKUP($I$16,'Packet size and rates'!G103:AH108, 19,FALSE())))*('Packet size and rates'!Y117/F17) -> 1.744896 | J22: =H22*I22 -> 1.7485312 | K22: =1000000*I22/(24*3600) -> 20.195556 | L22: =K22/8 -> 2.5244444 | M22: PEPSSI_DT2 | P22: 20.195556
E23: Status | F23: 0x685 | H23: =I$6+I$9 -> 1.0020833 | I23: =IF(I15=2,(VLOOKUP($I$16,'Packet size and rates'!G110:AH115, 13,FALSE())), (VLOOKUP($I$16,'Packet size and rates'!G103:AH108, 13,FALSE())))*('Packet size and rates'!S117/F18) -> 0.024576 | J23: =H23*I23 -> 0.0246272 | K23: =1000000*I23/(24*3600) -> 0.28444444 | L23: =K23/8 -> 0.035555556 | M23: INST_HSK_3 | P23: 0.28444444
E24: N2 | F24: 0x692 | H24: =IF(K$9="yes",I$9,0)+IF(K$6="yes",I$6,0) -> 1.0020833 | I24: =IF(I15=2,(VLOOKUP($I$16,'Packet size and rates'!G110:AH115, 25,FALSE())), (VLOOKUP($I$16,'Packet size and rates'!G103:AH108, 25,FALSE()))) -> 0.3798 | J24: =H24*I24 -> 0.38059125 | K24: =1000000*I24/(24*3600) -> 4.3958333 | L24: =K24/8 -> 0.54947917 | M24: PEPSSI_DT3 | P24: 4.3958333
E25: Trigger packet | F25: 0x68A | H25: =IF(K$9="yes",I$9,0)+IF(K$6="yes",I$6,0) -> 1.0020833 | I25: =IF(I15=2,(VLOOKUP($I$16,'Packet size and rates'!G110:AH115, 5,FALSE())), (VLOOKUP($I$16,'Packet size and rates'!G103:AH108, 5,FALSE()))) -> 0.35505 | J25: =H25*I25 -> 0.35578969 | K25: =1000000*I25/(24*3600) -> 4.109375 | L25: =K25/8 -> 0.51367188 | M25: PEPSSI_DT4 | P25: 4.109375
E26: Buffered Rates | F26: 0x697 | H26: =IF(K$9="yes",I$9,0)+IF(K$6="yes",I$6,0) -> 1.0020833 | I26: =IF(I15=2,(VLOOKUP($I$16,'Packet size and rates'!G110:AH115, 8,FALSE())), (VLOOKUP($I$16,'Packet size and rates'!G103:AH108, 8,FALSE()))) -> 1.408725 | J26: =H26*I26 -> 1.4116598 | K26: =1000000*I26/(24*3600) -> 16.304688 | L26: =K26/8 -> 2.0380859 | M26: DT2 if Mac102, otherwise DT3 | P26: 16.304688
E27: SubTotal | I27: =SUM(I21:I26) -> 4.390167 | J27: =SUM(J21:J26) -> 4.3993132 | K27: =SUM(K21:K26) -> 50.812118 | L27: =SUM(L21:L26) -> 6.3515148
E29: Power-on | J29: =1.6*G11 -> 1.6
E31: Total | J31: =J27+J29 -> 5.9993132 | T31: days
P32: not played | Q32: dt4 | R32: 159 | S32: 207 | T32: =S32-R32 -> 48 | U32: =V32*T32 -> 11.52 | V32: 0.24
I33: Mbits/day | J33: Mbits | K33: bps | L33: bytes/s | R33: 207 | S33: 218 | T33: =S33-R33 -> 11 | U33: =V33*T33 -> 4.18 | V33: 0.38
H34: N1/N3/Status | I34: =I21+I22+I23 -> 2.246592 | J34: =J21+J22+J23 -> 2.2512724 | K34: =K21+K22+K23 -> 26.002222 | L34: =L21+L22+L23 -> 3.2502778 | M34: DT1, DT2, HSK3 | N34: Survey | U34: =U33+U32 -> 15.7
H35: buff rates + N1/N3/Status | I35: =I26+I23+I22+I21 -> 3.655317 | J35: =J26+J23+J22+J21 -> 3.6629322 | K35: =K26+K23+K22+K21 -> 42.30691 | L35: =L26+L23+L22+L21 -> 5.2883637 | M35: DT1, DT2, HSK3 (if Macro102) | N35: PEPSSI_DT2 if macro 102 | Q35: 40.22 | R35: surv+br | S35: 207-218
H36: N2, buff rates, N1/N3/Status | I36: =I26+I24+I23+I22+I21 -> 4.035117 | J36: =J26+J24+J23+J22+J21 -> 4.0435235 | K36: =K26+K24+K23+K22+K21 -> 46.702743 | L36: =L26+L24+L23+L22+L21 -> 5.8378429 | M36: DT1, DT2, DT3,HSK3 (no macro102?)
H37: Trig Assess, N2, buff rates, N1/N3/Status | I37: =SUM(I21:I26) -> 4.390167 | J37: =SUM(J21:J26) -> 4.3993132 | K37: =SUM(K21:K26) -> 50.812118 | L37: =SUM(L21:L26) -> 6.3515148 | M37: DT1, DT2, DT3, DT4, HSK3
H38: N2 | I38: =I24 -> 0.3798 | J38: =J24 -> 0.38059125 | K38: =K24 -> 4.3958333 | L38: =L24 -> 0.54947917 | M38: DT3 if Macro 102 | R38: total swap | S38: total pepssi
H39: trig assess | I39: =I25 -> 0.35505 | J39: =J25 -> 0.35578969 | K39: =K25 -> 4.109375 | L39: =L25 -> 0.51367188 | M39: DT4 | Q39: 25096 | R39: 16 | S39: =T39+U39+V39 -> 41 | T39: 5 | U39: 6 | V39: 30
H40: Trig Assess, buff rates | I40: =I26+I25 -> 1.763775 | J40: =J26+J25 -> 1.7674495 | K40: =K26+K25 -> 20.414062 | L40: =L26+L25 -> 2.5517578 | M40: DT1, DT2, DT3, DT4, HSK3 | Q40: 25118 | R40: 18 | S40: =T40+U40+V40 -> 47 | T40: 5 | U40: 7 | V40: 35
H41: N1, N2, Status, Trig Assess | I41: =I21+I23+I24+I25 -> 1.236546 | J41: =J21+J23+J24+J25 -> 1.2391221 | K41: =K21+K23+K24+K25 -> 14.311875 | L41: =L21+L23+L24+L25 -> 1.7889844 | M41: DT1, DT3, DT4, HSK3 | Q41: 25138 | R41: 66 | S41: =T41+U41+V41 -> 54 | T41: 4 | U41: 8 | V41: 42
H42: N1, Status, Trig Assess | I42: =I21+I23+I25 -> 0.856746 | J42: =J21+J23+J25 -> 0.85853089 | K42: =K22+K25+K26 -> 40.609618 | L42: =L22+L25+L26 -> 5.0762023 | M42: DT1, DT4, HSK3 | Q42: 25159 | R42: 90 | S42: =T42+U42+V42 -> 146 | T42: 41 | V42: 105
H43: N3, buff rates | I43: =I26+I22 -> 3.153621 | J43: =J26+J22 -> 3.160191 | K43: =K26+K22 -> 36.500243 | L43: =L26+L22 -> 4.5625304 | M43: DT2 with macro 102 | O43: for ralph | Q43: rtcs | R43: 23
O44: =304-P44 -> 130 | P44: =R44+S44 -> 174 | Q44: 25181 | R44: 125 | S44: =T44+U44+V44 -> 49 | V44: 49
K45: swap | N45: pep | Q45: 25207 | R45: 40 | S45: =T45+U45+V45 -> 40 | V45: 40
...

Sheet 26179
C3: Load number: | E3: 26179
C4: First | E4: DOY | F4: Hour | G4: Min | H4: Days: | I4: Delta | K4: Burst enabled?
D5: Start: | E5: 179 | F5: 2 | G5: 45 | H5: =E5+(F5+G5/60)/24 -> 179.11458
D6: Stop: | E6: 201 | F6: 20 | G6: 10 | H6: =E6+(F6+G6/60)/24 -> 201.84028 | I6: =H6-H5 -> 22.725694 | K6: yes
C7: Second | O7: The fields in blue need to be updated for each load
D8: Start: | H8: =E8+(F8+G8/60)/24 -> 0 | M8: 219 | N8: 3 | O8: 27
D9: Stop: | H9: =E9+(F9+G9/60)/24 -> 0 | I9: =H9-H8 -> 0 | K9: yes | M9: =219+365-219+165 -> 530 | N9: 23 | O9: 0
E10: =365-219 -> 146 | F10: 165 | G10: =219+F10+E10 -> 530
C11: How many power-on instances are in this load?: | G11: 1
D13: Settings:
E14: N1 | F14: 360
E15: Macro 103/104? | F15: 104 | G15: --> | H15: N2mon = | I15: =IF(F16=101,3,IF(F15=103,3,2)) -> 2
E16: Macro 105-110? | F16: 105 | H16: macro used= | I16: =IF(F16=101,106, F16) -> 105 | J16: <-- if macro=101, then macro 103/104 field is ignored, and settings for macro 103/106 are automatically used
E17: N3 | F17: 900
E18: Status | F18: 1800
L19: Science
D20: Telemetry product: | H20: Days | I20: Mbits/day | J20: Total Mbits | K20: bps | L20: bytes/s
E21: N1 | F21: 0x691 | H21: =I$6+I$9 -> 22.725694 | I21: =IF(I15=2,(VLOOKUP($I$16,'Packet size and rates'!G110:AH115, 16,FALSE())), (VLOOKUP($I$16,'Packet size and rates'!G103:AH108, 16,FALSE())))*('Packet size and rates'!V117/F14) -> 0.47712 | J21: =H21*I21 -> 10.842883 | K21: =1000000*I21/(24*3600) -> 5.5222222 | L21: =K21/8 -> 0.69027778 | M21: PEPSSI_DT1 | P21: `
E22: N3 | F22: 0x693 | H22: =I$6+I$9 -> 22.725694 | I22: =IF(I15=2,(VLOOKUP($I$16,'Packet size and rates'!G110:AH115, 19,FALSE())), (VLOOKUP($I$16,'Packet size and rates'!G103:AH108, 19,FALSE())))*('Packet size and rates'!Y117/F17) -> 1.744896 | J22: =H22*I22 -> 39.653973 | K22: =1000000*I22/(24*3600) -> 20.195556 | L22: =K22/8 -> 2.5244444 | M22: PEPSSI_DT2 | P22: 20.195556
B23: =150/2.2 -> 68.181818 | E23: Status | F23: 0x685 | H23: =I$6+I$9 -> 22.725694 | I23: =IF(I15=2,(VLOOKUP($I$16,'Packet size and rates'!G110:AH115, 13,FALSE())), (VLOOKUP($I$16,'Packet size and rates'!G103:AH108, 13,FALSE())))*('Packet size and rates'!S117/F18) -> 0.024576 | J23: =H23*I23 -> 0.55850667 | K23: =1000000*I23/(24*3600) -> 0.28444444 | L23: =K23/8 -> 0.035555556 | M23: INST_HSK_3 | P23: 0.28444444
B24: =B23*1.2 -> 81.818182 | E24: N2 | F24: 0x692 | H24: =IF(K$9="yes",I$9,0)+IF(K$6="yes",I$6,0) -> 22.725694 | I24: =IF(I15=2,(VLOOKUP($I$16,'Packet size and rates'!G110:AH115, 25,FALSE())), (VLOOKUP($I$16,'Packet size and rates'!G103:AH108, 25,FALSE()))) -> 0.3798 | J24: =H24*I24 -> 8.6312187 | K24: =1000000*I24/(24*3600) -> 4.3958333 | L24: =K24/8 -> 0.54947917 | M24: PEPSSI_DT3 | P24: 4.3958333
E25: Trigger packet | F25: 0x68A | H25: =IF(K$9="yes",I$9,0)+IF(K$6="yes",I$6,0) -> 22.725694 | I25: =IF(I15=2,(VLOOKUP($I$16,'Packet size and rates'!G110:AH115, 5,FALSE())), (VLOOKUP($I$16,'Packet size and rates'!G103:AH108, 5,FALSE()))) -> 0.35505 | J25: =H25*I25 -> 8.0687578 | K25: =1000000*I25/(24*3600) -> 4.109375 | L25: =K25/8 -> 0.51367188 | M25: PEPSSI_DT4 | P25: 4.109375
B26: 80 gm protein | E26: Buffered Rates | F26: 0x697 | H26: =IF(K$9="yes",I$9,0)+IF(K$6="yes",I$6,0) -> 22.725694 | I26: =IF(I15=2,(VLOOKUP($I$16,'Packet size and rates'!G110:AH115, 8,FALSE())), (VLOOKUP($I$16,'Packet size and rates'!G103:AH108, 8,FALSE()))) -> 1.408725 | J26: =H26*I26 -> 32.014254 | K26: =1000000*I26/(24*3600) -> 16.304688 | L26: =K26/8 -> 2.0380859 | M26: DT3 nominally, DT2 if Mac102 | P26: 16.304688
B27: most metabolic organ is muscle | E27: SubTotal | I27: =SUM(I21:I26) -> 4.390167 | J27: =SUM(J21:J26) -> 99.769594 | K27: =SUM(K21:K26) -> 50.812118 | L27: =SUM(L21:L26) -> 6.3515148
B28: fat slows things down
B29: don't want to lose muscle | E29: Power-on | J29: =1.6*G11 -> 1.6
E31: Total | J31: =J27+J29 -> 101.36959
I33: Mbits/day | J33: Mbits | K33: bps | L33: bytes/s
H34: N1/N3/Status | I34: =I21+I22+I23 -> 2.246592 | J34: =J21+J22+J23 -> 51.055363 | K34: =K21+K22+K23 -> 26.002222 | L34: =L21+L22+L23 -> 3.2502778 | M34: DT1, DT2, HSK3 (no Macro 102)
H35: buff rates + N1/N3/Status | I35: =I26+I23+I22+I21 -> 3.655317 | J35: =J26+J23+J22+J21 -> 83.069617 | K35: =K26+K23+K22+K21 -> 42.30691 | L35: =L26+L23+L22+L21 -> 5.2883637 | M35: DT1, DT2, HSK3 (if Macro102)
H36: N2, buff rates, N1/N3/Status | I36: =I26+I24+I23+I22+I21 -> 4.035117 | J36: =J26+J24+J23+J22+J21 -> 91.700836 | K36: =K26+K24+K23+K22+K21 -> 46.702743 | L36: =L26+L24+L23+L22+L21 -> 5.8378429 | M36: DT1, DT2, DT3,HSK3
H37: Trig Assess, N2, buff rates, N1/N3/Status | I37: =SUM(I21:I26) -> 4.390167 | J37: =SUM(J21:J26) -> 99.769594 | K37: =SUM(K21:K26) -> 50.812118 | L37: =SUM(L21:L26) -> 6.3515148 | M37: DT1, DT2, DT3, DT4, HSK3
H38: N2 | I38: =I24 -> 0.3798 | J38: =J24 -> 8.6312187 | K38: =K24 -> 4.3958333 | L38: =L24 -> 0.54947917 | M38: DT3 if Macro 102
H39: trig assess | I39: =I25 -> 0.35505 | J39: =J25 -> 8.0687578 | K39: =K25 -> 4.109375 | L39: =L25 -> 0.51367188 | M39: DT4
H40: Trig Assess, buff rates | I40: =I26+I25 -> 1.763775 | J40: =J26+J25 -> 40.083012 | K40: =K26+K25 -> 20.414062 | L40: =L26+L25 -> 2.5517578 | M40: Can't command this (buff rates either comes with N2 or N3 depending on Macro 102)
H41: N1, N2, Status, Trig Assess | I41: =I21+I23+I24+I25 -> 1.236546 | J41: =J21+J23+J24+J25 -> 28.101367 | K41: =K21+K23+K24+K25 -> 14.311875 | L41: =L21+L23+L24+L25 -> 1.7889844 | M41: DT1, DT3, DT4, HSK3 (no Macro 102)
H42: N1, Status, Trig Assess | I42: =I21+I23+I25 -> 0.856746 | J42: =J21+J23+J25 -> 19.470148 | K42: =K22+K25+K26 -> 40.609618 | L42: =L22+L25+L26 -> 5.0762023 | M42: DT1, DT4, HSK3
H43: N3, buff rates | I43: =I26+I22 -> 3.153621 | J43: =J26+J22 -> 71.668227 | K43: =K26+K22 -> 36.500243 | L43: =L26+L22 -> 4.5625304 | M43: DT2 with macro 102
J45: =J34+J38+J39+J26 -> 99.769594
J46: 1.6
...

Sheet 26201
C3: Load number: | E3: 25207
C4: First | E4: DOY | F4: Hour | G4: Min | H4: Days: | I4: Delta | K4: Burst enabled?
D5: Start: | E5: 179 | F5: 0 | G5: 0 | H5: =E5+(F5+G5/60)/24 -> 179
D6: Stop: | E6: 201 | F6: 0 | G6: 0 | H6: =E6+(F6+G6/60)/24 -> 201 | I6: =H6-H5 -> 22 | K6: yes
C7: Second | O7: The fields in blue need to be updated for each load
D8: Start: | H8: =E8+(F8+G8/60)/24 -> 0 | M8: 219 | N8: 3 | O8: 27
D9: Stop: | H9: =E9+(F9+G9/60)/24 -> 0 | I9: =H9-H8 -> 0 | K9: yes | M9: =219+365-219+165 -> 530 | N9: 23 | O9: 0
E10: =365-219 -> 146 | F10: 165 | G10: =219+F10+E10 -> 530
C11: How many power-on instances are in this load?: | G11: 1
D13: Settings:
E14: N1 | F14: 360
E15: Macro 103/104? | F15: 103 | G15: --> | H15: N2mon = | I15: =IF(F16=101,3,IF(F15=103,3,2)) -> 3
E16: Macro 105-110? | F16: 109 | H16: macro used= | I16: =IF(F16=101,106, F16) -> 109 | J16: <-- if macro=101, then macro 103/104 field is ignored, and settings for macro 103/106 are automatically used
E17: N3 | F17: 7200
E18: Status | F18: 1800
L19: Science
D20: Telemetry product: | H20: Days | I20: Mbits/day | J20: Total Mbits | K20: bps | L20: bytes/s
E21: N1 | F21: 0x691 | H21: =I$6+I$9 -> 22 | I21: =IF(I15=2,(VLOOKUP($I$16,'Packet size and rates'!G110:AH115, 16,FALSE())), (VLOOKUP($I$16,'Packet size and rates'!G103:AH108, 16,FALSE())))*('Packet size and rates'!V117/F14) -> 0.47712 | J21: =H21*I21 -> 10.49664 | K21: =1000000*I21/(24*3600) -> 5.5222222 | L21: =K21/8 -> 0.69027778 | M21: PEPSSI_DT1 | P21: `
E22: N3 | F22: 0x693 | H22: =I$6+I$9 -> 22 | I22: =IF(I15=2,(VLOOKUP($I$16,'Packet size and rates'!G110:AH115, 19,FALSE())), (VLOOKUP($I$16,'Packet size and rates'!G103:AH108, 19,FALSE())))*('Packet size and rates'!Y117/F17) -> 0.218112 | J22: =H22*I22 -> 4.798464 | K22: =1000000*I22/(24*3600) -> 2.5244444 | L22: =K22/8 -> 0.31555556 | M22: PEPSSI_DT2 | P22: 20.195556
E23: Status | F23: 0x685 | H23: =I$6+I$9 -> 22 | I23: =IF(I15=2,(VLOOKUP($I$16,'Packet size and rates'!G110:AH115, 13,FALSE())), (VLOOKUP($I$16,'Packet size and rates'!G103:AH108, 13,FALSE())))*('Packet size and rates'!S117/F18) -> 0.024576 | J23: =H23*I23 -> 0.540672 | K23: =1000000*I23/(24*3600) -> 0.28444444 | L23: =K23/8 -> 0.035555556 | M23: INST_HSK_3 | P23: 0.28444444
E24: N2 | F24: 0x692 | H24: =IF(K$9="yes",I$9,0)+IF(K$6="yes",I$6,0) -> 22 | I24: =IF(I15=2,(VLOOKUP($I$16,'Packet size and rates'!G110:AH115, 25,FALSE())), (VLOOKUP($I$16,'Packet size and rates'!G103:AH108, 25,FALSE()))) -> 1.5192 | J24: =H24*I24 -> 33.4224 | K24: =1000000*I24/(24*3600) -> 17.583333 | L24: =K24/8 -> 2.1979167 | M24: PEPSSI_DT3 | P24: 4.3958333
E25: Trigger packet | F25: 0x68A | H25: =IF(K$9="yes",I$9,0)+IF(K$6="yes",I$6,0) -> 22 | I25: =IF(I15=2,(VLOOKUP($I$16,'Packet size and rates'!G110:AH115, 5,FALSE())), (VLOOKUP($I$16,'Packet size and rates'!G103:AH108, 5,FALSE()))) -> 0.2367 | J25: =H25*I25 -> 5.2074 | K25: =1000000*I25/(24*3600) -> 2.7395833 | L25: =K25/8 -> 0.34244792 | M25: PEPSSI_DT4 | P25: 4.109375
E26: Buffered Rates | F26: 0x697 | H26: =IF(K$9="yes",I$9,0)+IF(K$6="yes",I$6,0) -> 22 | I26: =IF(I15=2,(VLOOKUP($I$16,'Packet size and rates'!G110:AH115, 8,FALSE())), (VLOOKUP($I$16,'Packet size and rates'!G103:AH108, 8,FALSE()))) -> 0.93915 | J26: =H26*I26 -> 20.6613 | K26: =1000000*I26/(24*3600) -> 10.869792 | L26: =K26/8 -> 1.358724 | M26: DT2 if Mac102, otherwise DT3 | P26: 16.304688
E27: SubTotal | I27: =SUM(I21:I26) -> 3.414858 | J27: =SUM(J21:J26) -> 75.126876 | K27: =SUM(K21:K26) -> 39.523819 | L27: =SUM(L21:L26) -> 4.9404774
E29: Power-on | J29: =1.6*G11 -> 1.6
E31: Total | J31: =J27+J29 -> 76.726876
I33: Mbits/day | J33: Mbits | K33: bps | L33: bytes/s
H34: N1/N3/Status | I34: =I21+I22+I23 -> 0.719808 | J34: =J21+J22+J23 -> 15.835776 | K34: =K21+K22+K23 -> 8.3311111 | L34: =L21+L22+L23 -> 1.0413889 | M34: DT1, DT2, HSK3 (no Macro 102) | N34: DT1, DT2, HSK3 (no Macro 102)
H35: buff rates + N1/N3/Status | I35: =I26+I23+I22+I21 -> 1.658958 | J35: =J26+J23+J22+J21 -> 36.497076 | K35: =K26+K23+K22+K21 -> 19.200903 | L35: =L26+L23+L22+L21 -> 2.4001128 | M35: DT1, DT2, HSK3 (if Macro102) | N35: DT1, DT2, HSK3 (if Macro102)
H36: N2, buff rates, N1/N3/Status | I36: =I26+I24+I23+I22+I21 -> 3.178158 | J36: =J26+J24+J23+J22+J21 -> 69.919476 | K36: =K26+K24+K23+K22+K21 -> 36.784236 | L36: =L26+L24+L23+L22+L21 -> 4.5980295 | M36: DT1, DT2, DT3,HSK3 | N36: DT1, DT2, DT3,HSK3
H37: Trig Assess, N2, buff rates, N1/N3/Status | I37: =SUM(I21:I26) -> 3.414858 | J37: =SUM(J21:J26) -> 75.126876 | K37: =SUM(K21:K26) -> 39.523819 | L37: =SUM(L21:L26) -> 4.9404774 | M37: DT1, DT2, DT3, DT4, HSK3 | N37: DT1, DT2, DT3, DT4, HSK3
H38: N2 | I38: =I24 -> 1.5192 | J38: =J24 -> 33.4224 | K38: =K24 -> 17.583333 | L38: =L24 -> 2.1979167 | M38: DT3 if Macro 102 | N38: DT3 if Macro 102
H39: trig assess | I39: =I25 -> 0.2367 | J39: =J25 -> 5.2074 | K39: =K25 -> 2.7395833 | L39: =L25 -> 0.34244792 | M39: DT4 | N39: DT4
H40: Trig Assess, buff rates | I40: =I26+I25 -> 1.17585 | J40: =J26+J25 -> 25.8687 | K40: =K26+K25 -> 13.609375 | L40: =L26+L25 -> 1.7011719 | M40: Can't command this (buff rates either comes with N2 or N3 depending on Macro 102) | N40: Can't command this (buff rates either comes with N2 or N3 depending on Macro 102)
H41: N1, N2, Status, Trig Assess | I41: =I21+I23+I24+I25 -> 2.257596 | J41: =J21+J23+J24+J25 -> 49.667112 | K41: =K21+K23+K24+K25 -> 26.129583 | L41: =L21+L23+L24+L25 -> 3.2661979 | M41: DT1, DT3, DT4, HSK3 (no Macro 102) | N41: DT1, DT3, DT4, HSK3 (no Macro 102)
H42: N1, Status, Trig Assess | I42: =I21+I23+I25 -> 0.738396 | J42: =J21+J23+J25 -> 16.244712 | K42: =K22+K25+K26 -> 16.133819 | L42: =L22+L25+L26 -> 2.0167274 | M42: DT1, DT4, HSK3 | N42: DT1, DT4, HSK3
H43: N3, buff rates | I43: =I26+I22 -> 1.157262 | J43: =J26+J22 -> 25.459764 | K43: =K26+K22 -> 13.394236 | L43: =L26+L22 -> 1.6742795 | M43: DT2 with macro 102 | N43: DT2 with macro 102
I72: 347/0119-45/0454 hib | J72: 164

Sheet 26222
C3: Load number: | E3: 25207
C4: First | E4: DOY | F4: Hour | G4: Min | H4: Days: | I4: Delta | K4: Burst enabled?
D5: Start: | E5: 222 | F5: 0 | G5: 0 | H5: =E5+(F5+G5/60)/24 -> 222
D6: Stop: | E6: 243 | F6: 0 | G6: 0 | H6: =E6+(F6+G6/60)/24 -> 243 | I6: =H6-H5 -> 21 | K6: yes
C7: Second | O7: The fields in blue need to be updated for each load
D8: Start: | H8: =E8+(F8+G8/60)/24 -> 0 | M8: 219 | N8: 3 | O8: 27
D9: Stop: | H9: =E9+(F9+G9/60)/24 -> 0 | I9: =H9-H8 -> 0 | K9: yes | M9: =219+365-219+165 -> 530 | N9: 23 | O9: 0
C11: How many power-on instances are in this load?: | G11: 0
D13: Settings:
E14: N1 | F14: 360
E15: Macro 103/104? | F15: 103 | G15: --> | H15: N2mon = | I15: =IF(F16=101,3,IF(F15=103,3,2)) -> 3
E16: Macro 105-110? | F16: 109 | H16: macro used= | I16: =IF(F16=101,106, F16) -> 109 | J16: <-- if macro=101, then macro 103/104 field is ignored, and settings for macro 103/106 are automatically used
E17: N3 | F17: 7200
E18: Status | F18: 1800
L19: Science
D20: Telemetry product: | H20: Days | I20: Mbits/day | J20: Total Mbits | K20: bps | L20: bytes/s
