Workbook
Name Daily_10M: #REF!
Name Daily_12H: #REF!
Name Daily_1H: #REF!
Name Daily_20M: #REF!
Name Daily_24H: #REF!
Name Daily_2H: #REF!
Name Daily_2M: #REF!
Name Daily_30M: #REF!
Name Daily_3H: #REF!
Name Daily_5M: #REF!
Name Daily_64s: #REF!
Name Daily_6H: #REF!
Name Daily_NEVER: #REF!
Name Yearly_10M: #REF!
Name Yearly_12H: #REF!
Name Yearly_1H: #REF!
Name Yearly_20M: #REF!
Name Yearly_24H: #REF!
Name Yearly_2H: #REF!
Name Yearly_2M: #REF!
Name Yearly_30M: #REF!
Name Yearly_3H: #REF!
Name Yearly_5M: #REF!
Name Yearly_64S: #REF!
Name Yearly_6H: #REF!
Name Yearly_NEVER: #REF!

Sheet pb_calc_pre_2025
C2: V4 operation in sequence 22080
H3: packet size (bits)
H4: max bits | I4: historical size | J4: Enabled? | K4: integration time (s) | L4: bps | M4: sec/day | N4: data collection (days) | P4: Total recorded data (Mbits)/year | Q4: Total downlinked data (Mbits)/year
F5: Survey Data
G6: N1 | H6: 5680 | I6: 2400 | J6: 1 | K6: 3600 | L6: =J6*I6/K6 -> 0.66666667 | M6: =3600*24 -> 86400 | N6: 22 | P6: =L6*M6*N6/1000000 -> 1.2672 | Q6: =P6 -> 1.2672
G7: N2 normal | H7: 4928 | I7: 1920 | J7: 1 | K7: 90 | L7: =J7*I7/K7 -> 21.333333 | M7: =3600*24 -> 86400 | N7: =N6 -> 22 | P7: =L7*M7*N7/1000000 -> 40.5504 | Q7: =P7 -> 40.5504
G8: N3+ extra | H8: 64000 | I8: 20000 | J8: 1 | K8: 7200 | L8: =J8*I8/K8 -> 2.7777778 | M8: =3600*24 -> 86400 | N8: =N6 -> 22 | P8: =L8*M8*N8/1000000 -> 5.28 | Q8: =P8 -> 5.28
G9: HK/status | H9: 512 | I9: =H9 -> 512 | J9: 1 | K9: 1800 | L9: =J9*I9/K9 -> 0.28444444 | M9: =3600*24 -> 86400 | N9: =N6 -> 22 | P9: =L9*M9*N9/1000000 -> 0.540672 | Q9: =P9 -> 0.540672
K10: =IF(AND( (K6/K7)=INT(K6/K7), (K8/K7)=INT(K8/K7) ), " ", "error") | P10: =SUM(P6:P9) -> 47.638272 | Q10: =SUM(Q6:Q9) -> 47.638272
H12: max bits | I12: historical size | J12: Enabled? | K12: integration time (s) | L12: bps | M12: sec/day | P12: Total recorded data (Mbits)/year | Q12: Total downlinked data (Mbits)/year
F13: Burst Data
G14: High Time Resolution Buffered Rate (10) Data | H14: 8480 | I14: 2900 | J14: 1 | K14: =I22*64 -> 1280 | L14: =J14*I14/K14 -> 2.265625 | M14: =3600*24 -> 86400 | P14: =L14*M14*I25*((I23+I24))/1000000 -> 0 | Q14: =L14*M14*I26*((I23+I24))/1000000 -> 0
G15: Trigger assessment data | H15: 992 | I15: 600 | J15: 1 | K15: =I22*64 -> 1280 | L15: =J15*I15/K15 -> 0.46875 | M15: =3600*24 -> 86400 | P15: =L15*M15*I25*((I23+I24))/1000000 -> 0 | Q15: =L15*M15*I26*((I23+I24))/1000000 -> 0
G16: N2 burst data | H16: =H7 -> 4928 | I16: 1400 | J16: 1 | K16: =I22 -> 20 | L16: =J16*I16/K16 -> 70 | M16: =3600*24 -> 86400 | P16: =L16*M16*I25*I24/1000000 -> 0 | Q16: =L16*M16*I26*I24/1000000 -> 0
P17: =SUM(P14:P16) -> 0 | Q17: =SUM(Q14:Q16) -> 0
F19: Total | P19: =P10+P17 -> 47.638272 | Q19: =Q10+Q17 -> 47.638272 | R19: Mbits
F21: Assumptions
F22: Commanded N2Monitor int time | I22: 20
F23: pre-trigger data (days) | I23: =0.7*I22/10 -> 1.4
F24: post-trigger data (days) | I24: 2
F25: Number of bursts occurring/year assumed | I25: 0
F26: # of N2 bursts downlinked/year assumed | I26: 0
Y28: No MLI
N29: =1/30/24 -> 0.0013888889
C32: Power On Portion of V5 load and test
H33: packet size (bits)
H34: max bits | I34: historical size | J34: Enabled? | K34: integration time (s) | L34: bps | M34: sec/day | N34: data collection (days) | P34: Total recorded data (Mbits)/year | Q34: Total downlinked data (Mbits)/year
F35: Survey Data
G36: N1 | H36: 5680 | I36: 3200 | J36: 1 | K36: 3600 | L36: =J36*I36/K36 -> 0.88888889 | M36: =3600*24 -> 86400 | N36: =1/24 -> 0.041666667 | P36: =L36*M36*N36/1000000 -> 0.0032 | Q36: =P36 -> 0.0032
G37: N2 normal | H37: 4928 | I37: 1920 | J37: 1 | K37: 90 | L37: =J37*I37/K37 -> 21.333333 | M37: =3600*24 -> 86400 | N37: =N36 -> 0.041666667 | P37: =L37*M37*N37/1000000 -> 0.0768 | Q37: =P37 -> 0.0768
C38: The historical size of the packets | G38: N3+ extra | H38: 64000 | I38: 32080 | J38: 1 | K38: 7200 | L38: =J38*I38/K38 -> 4.4555556 | M38: =3600*24 -> 86400 | N38: =N36 -> 0.041666667 | P38: =L38*M38*N38/1000000 -> 0.01604 | Q38: =P38 -> 0.01604
C39: probably are too high. | E39: --> | G39: HK/status | H39: 512 | I39: =H39 -> 512 | J39: 1 | K39: 1 | L39: =J39*I39/K39 -> 512 | M39: =3600*24 -> 86400 | N39: =N36 -> 0.041666667 | P39: =L39*M39*N39/1000000 -> 1.8432 | Q39: =P39 -> 1.8432
K40: =IF(AND( (K36/K37)=INT(K36/K37), (K38/K37)=INT(K38/K37) ), " ", "error") | P40: =SUM(P36:P39) -> 1.93924 | Q40: =SUM(Q36:Q39) -> 1.93924
H42: max bits | I42: historical size | J42: Enabled? | K42: integration time (s) | L42: bps | M42: sec/day | P42: Total recorded data (Mbits)/year | Q42: Total downlinked data (Mbits)/year
F43: Burst Data
G44: High Time Resolution Buffered Rate (10) Data | H44: 8480 | I44: =I$14 -> 2900 | J44: 1 | K44: =I52*64 -> 1280 | L44: =J44*I44/K44 -> 2.265625 | M44: =3600*24 -> 86400 | P44: =L44*M44*I55*((I53+I54))/1000000 -> 0 | Q44: =L44*M44*I56*((I53+I54))/1000000 -> 0
G45: Trigger assessment data | H45: 992 | I45: =I$15 -> 600 | J45: 1 | K45: =I52*64 -> 1280 | L45: =J45*I45/K45 -> 0.46875 | M45: =3600*24 -> 86400 | P45: =L45*M45*I55*((I53+I54))/1000000 -> 0 | Q45: =L45*M45*I56*((I53+I54))/1000000 -> 0
G46: N2 burst data | H46: =H37 -> 4928 | I46: =I$16 -> 1400 | J46: 1 | K46: =I52 -> 20 | L46: =J46*I46/K46 -> 70 | M46: =3600*24 -> 86400 | P46: =L46*M46*I55*I54/1000000 -> 0 | Q46: =L46*M46*I56*I54/1000000 -> 0
P47: =SUM(P44:P46) -> 0 | Q47: =SUM(Q44:Q46) -> 0
F49: Total | P49: =P40+P47 -> 1.93924 | Q49: =Q40+Q47 -> 1.93924 | R49: Mbits
...

Sheet 2025_pb
M2: not played back swap | N2: 126 | O2: 159 | P2: =O2-N2 -> 33 | Q2: =P2*S6 -> 31.728378
N3: 159 | O3: 181 | P3: =O3-N3 -> 22 | Q3: =P3*X6 -> 56.201821 | V3: =4.513307/V10 -> 0.92947581 | X3: =25/X6 -> 9.7861598
N4: 181 | O4: 218 | P4: =O4-N4 -> 37 | Q4: =P4*S6 -> 35.574242
Q5: =Q4+Q3+Q2 -> 123.50444
R6: Mbits/day | S6: 0.961466 | U6: Mbits/day | V6: =V9*8*86400/1000000 -> 2.640384 | W6: 2.546459 | X6: 2.5546282
R7: Non-hibernatio | S7: RT = 30 MIN | U7: hibernation | V7: RT = 10 MIN | Z7: DT1 | AA7: DT2 | AB7: HSK3 | AC7: DT2 if 102 | AD7: DT3 | AE7: DT4
R8: swap gain by/s | S8: 14.778455 | T8: =T9*1.1 -> 0.40055257 | U8: swap gain by/s | V8: 14.778455 | W8: should be: | X8: latest: | Z8: N1 | AA8: N3 | AB8: Status | AC8: Buff Rates | AD8: N2 | AE8: Trig Assess | AF8: Mbits/d
N9: 125Mb/2.55Mb/d | O9: =125/X6 -> 48.930799 | Q9: 0.961466 | R9: swap bytes/s | S9: =S6*1000000/(8*86400) -> 1.3910098 | T9: =S9/V9 -> 0.3641387 | U9: swap bytes/s | V9: 3.82 | W9: =W6*1000000/(8*86400) -> 3.6841131 | X9: =X6*1000000/(8*86400) -> 3.695932 | Y9: total bps | Z9: bps | AA9: bps | AB9: bps | AC9: bps | AD9: bps | AE9: bps
N10: end of 25181 | O10: =347+49-365 -> 31 | S10: erroneously used in 96/118 | T10: MACRO 101 | U10: pepssi bytes/s | V10: =Y10/8 -> 4.8557552 | W10: w N2 + DT4 | X10: N1 = 120 | Y10: =SUM(Z10:AE10) -> 38.846042 | Z10: 16.566667 | AA10: 2.5244444 | AB10: 0.28444444 | AC10: 10.869792 | AD10: 5.8611111 | AE10: 2.7395833
M11: plus gain | N11: days pb 207 | O11: =(40-6)/X6 -> 13.309177 | S11: should have used for 96/118 | T11: MACRO 101 | U11: pepssi bytes/s | V11: =Y11/8 -> 4.5133073 | W11: w N2 no DT4 | X11: N1 = 120 | Y11: =SUM(Z11:AE11) -> 36.106458 | Z11: 16.566667 | AA11: 2.5244444 | AB11: 0.28444444 | AC11: 10.869792 | AD11: 5.8611111 | AF11: =Y11*86400/1000000 -> 3.119598
N12: =(83-45)*X6 -> 97.075872 | S12: 25159 | T12: MAC 103/110 | U12: pepssi bytes/s | V12: =Y12/8 -> 3.0903906 | W12: No N2/DT4 | X12: N1 = 180 | Y12: =SUM(Z12:AE12) -> 24.723125 | Z12: 11.044444 | AA12: 2.5244444 | AB12: 0.28444444 | AC12: 10.869792 | AF12: =Y12*86400/1000000 -> 2.136078
P13: ?? | S13: 25139 | T13: MACRO 101 | U13: pepssi bytes/s | V13: =Y13/8 -> 3.7806684 | W13: No N2/DT4 | X13: N1 = 120 | Y13: =SUM(Z13:AE13) -> 30.245347 | Z13: 16.566667 | AA13: 2.5244444 | AB13: 0.28444444 | AC13: 10.869792 | AF13: =Y13*86400/1000000 -> 2.613198
S14: 25159 | T14: MAC 103/110 | U14: pepssi bytes/s | V14: =Y14/8 -> 0.34244792 | W14: DT4 | X14: N1 = 180 | Y14: =SUM(Z14:AE14) -> 2.7395833 | AE14: 2.7395833 | AF14: =Y14*86400/1000000 -> 0.2367 | AG14: =AF14*21 -> 4.9707
S15: 25159 no macros | T15: ‘survey’ only | U15: pepssi bytes/s | V15: =Y15/8 -> 1.7316667 | W15: N1/N3/St | X15: N1 = 180 | Y15: =SUM(Z15:AE15) -> 13.853333 | Z15: 11.044444 | AA15: 2.5244444 | AB15: 0.28444444 | AF15: =Y15*86400/1000000 -> 1.196928
Q16: NO ==> not 120 | S16: 25181 no macros | T16: ‘survey’ only | U16: pepssi bytes/s | V16: =Y16/8 -> 2.4219444 | W16: N1/N3/St | X16: N1 = 120 | Y16: =SUM(Z16:AE16) -> 19.375556 | Z16: 16.566667 | AA16: 2.5244444 | AB16: 0.28444444 | AF16: =Y16*86400/1000000 -> 1.674048
Q17: n1/n2/st/ta | S17: 25181 | T17: MAC 103/105 | U17: pepssi bytes/s | V17: =Y17/8 -> 2.1248785 | W17: No N3/BuffR | X17: N1 = 180 | Y17: =SUM(Z17:AE17) -> 16.999028 | Z17: 11.044444 | AB17: 0.28444444 | AD17: 2.9305556 | AE17: 2.7395833 | AF17: =Y17*86400/1000000 -> 1.468716
Q18: n3/br | S18: 25181 | T18: MAC 103/105 | U18: pepssi bytes/s | V18: =Y18/8 -> 1.6742795 | W18: only N3/Buff | X18: N1 = 180 | Y18: =SUM(Z18:AE18) -> 13.394236 | AA18: 2.5244444 | AC18: 10.869792 | AF18: =Y18*86400/1000000 -> 1.157262
S19: 25181 | T19: MAC 103/105 | U19: pepssi bytes/s | V19: =Y19/8 -> 3.799158 | W19: all | X19: N1 = 180 | Y19: =SUM(Z19:AE19) -> 30.393264 | Z19: 11.044444 | AA19: 2.5244444 | AB19: 0.28444444 | AC19: 10.869792 | AD19: 2.9305556 | AE19: 2.7395833 | AF19: =Y19*86400/1000000 -> 2.625978
S20: 25159 | T20: MAC 103/110 | U20: pepssi bytes/s | V20: =Y20/8 -> 52.75 | W20: N2 only | X20: N1 = 180 | Y20: =SUM(Z20:AE20) -> 422 | AD20: 422 | AF20: =Y20*86400/1000000 -> 36.4608
T21: 25207 MAC 104/105 | U21: pepssi bytes/s | V21: =Y21/8 -> 1.7889844 | W21: N1/N2/TA/St | X21: N1=300 | Y21: =SUM(Z21:AE21) -> 14.311875 | Z21: 5.5222222 | AB21: 0.28444444 | AD21: 4.3958333 | AE21: 4.109375 | AF21: =Y21*86400/1000000 -> 1.236546
U23: pwron bytes | V23: 197375
P24: 097 00:46:28 | Q24: 096 16:15:01 | R24: 606262016 | S24: 8 | T24: C&DH #1 | U24: TT 12 | V24: SWAP_LVPS_POWER CDBOTH ON | W24: Turn ON SWAP | X24: K1SW_A4_SWAP_Daily_ON_096_1_power_on
O25: 25096 gain test | P25: 099 11:31:17 | Q25: 099 03:00:01 | R25: 606473516 | S25: 7 | T25: C&DH #1 | U25: TT 77 | V25: SWAP_LVPS_POWER CDBOTH ON | W25: Turn ON SWAP | X25: K1SW_A4_SWAP_GAIN_099_1
P26: 099 13:21:29 | Q26: 099 04:50:13 | R26: 606480128 | S26: 0 | T26: SWAP #1 | U26: TT 086 | V26: SWAP_TLM_HK_RATE 1H MACRO=EXEC | X26: K1SW_A4_SWAP_OFF_099__A4
P27: =R26-R25 -> 6612 | R27: 589335049 | S27: 589362052 | T27: =S27-R27 -> 27003 | U27: 110684 | V27: =U27/T27 -> 4.098952
M28: =(20+16/24)*38.9*86400/1000000 -> 69.45984 | P28: 099 13:54:49 | Q28: 099 05:23:33 | R28: 606482128 | S28: 1 | T28: C&DH #1 | U28: TT 87 | V28: SSR_LO_RCRD_SYNC SWAP_DT1 | X28: K1SW_A4_Refresh_All_099 | AD28: =11000000/500 -> 22000 | AE28: =AD28/3600 -> 6.1111111 | AG28: remaining
P29: 25096 | U29: =V23 -> 197375 | W29: Mbits/sec | X29: 2.70622e-05 | AB29: bytes using corrected rates | AE29: =11000000/500 -> 22000 | AF29: =AE29/3600 -> 6.1111111 | AH29: on track | AI29: Mbit dl
P30: track | Q30: start met | R30: end met | S30: seconds | T30: calculated bytes | U30: power ons | V30: total calc bytes | W30: bytes avail | X30: difference | AA30: pb report | AB30: calculated | AC30: actual Mbits | AD30: delta | AE30: delta | AH30: rel to S | AJ30: =AJ31+AJ33+AJ34 -> 31.701153
L31: 96/16:15 | M31: 99/03:01 | N31: pwron to gain | O31: 111/08:19 | P31: 111_1 | Q31: =R24-20 -> 606261996 | R31: =R25 -> 606473516 | S31: =R31-Q31 -> 211520 | T31: =S31*$V$9 -> 808006.4 | U31: 0 | V31: =T31+U31*$V$23 -> 808006.4 | W31: =Y31*1000000/8 -> 1085211.8 | X31: =W31-V31 -> 277205.35 | Y31: =8.681694 -> 8.681694 | AA31: 344216 | AB31: =S31*$S$9 -> 294226.4 | AC31: =AB31*8/1000000 -> 2.3538112 | AD31: =AB31+AB32 -> 1088101.4 | AE31: =AC31+AC32 -> 8.7048112 | AF31: TRK_111_1 | AG31: 111/08:19 | AH31: =X31*8/1000000 -> 2.2176428 | AI31: =V31*8/1000000 -> 6.4640512 | AJ31: 8.681694 | AK31: TRK_111_1 | AL31: 2025-111T08:34:01 | AM31: 0.80021 | AN31: 6 | AO31: 1.786772 | AP31: 0.986556 | AQ31: 8.681694
K32: gain test | L32: 99/03:01 | M32: 99/04:50 | N32: 5.58 | P32: 111_1 | Q32: =R31-1 -> 606473515 | R32: =R26 -> 606480128 | S32: =R32-Q32 -> 6613 | T32: =N32*1000000/8 -> 697500 | U32: 0 | V32: =T32+U32*$V$23 -> 697500 | W32: =X31 -> 277205.35 | X32: =W32-V32 -> -420294.65 | AA32: 677415 | AB32: =AC32*1000000/8 -> 793875 | AC32: 6.351 | AD32: =AB32+AB31-W31 -> 2889.6509 | AE32: =AC32+AC31-Y31 -> 0.023117207
K33: post gain | L33: 99/04:50 | M33: 103/21:12 | O33: 112/00:34 | P33: 112_1 | Q33: =R32-1 -> 606480127 | R33: =((W33)/$V$9)+Q33 -> 6.0688464e+08 | S33: =R33-Q33 -> 404514.65 | T33: =S33*$V$9 -> 1545246 | U33: 0 | V33: =T33+U33*$V$23 -> 1545246 | W33: =Y33*1000000/8+X32 -> 1545246 | X33: =W33-V33 -> -6.8917871e-08 | Y33: =AJ33 -> 15.724325 | AA33: 647088 | AB33: =S33*$S$9 -> 562683.86 | AC33: =AB33*8/1000000 -> 4.5014709 | AD33: =AB33-V33 -> -982562.11 | AE33: =AD33*8/1000000 -> -7.8604969 | AF33: =AK33 -> TRK_112_1 | AG33: 112/00:34 | AH33: =X33*8/1000000 -> -5.5134296e-13 | AI33: =V33*8/1000000 -> 12.361968 | AJ33: 15.724325 | AK33: TRK_112_1 | AL33: 2025-112T00:49:01 | AM33: 0.23065 | AN33: 6 | AO33: 2.017511 | AP33: 1.786855 | AQ33: 15.724325
L34: 103/21:12 | M34: 106/15:30 | O34: 112/18:29 | P34: 112_2 | Q34: =R33-1 -> 6.0688464e+08 | R34: =((W34)/$V$9)+Q34 -> 6.0712336e+08 | S34: =R34-Q34 -> 238715.12 | T34: =S34*$V$9 -> 911891.75 | U34: 0 | V34: =T34+U34*$V$23 -> 911891.75 | W34: =Y34*1000000/8 -> 911891.75 | X34: =W34-V34 -> -8.8126399e-08 | Y34: =AJ34 -> 7.295134 | AA34: 323548 | AB34: =S34*$S$9 -> 332055.08 | AC34: =AB34*8/1000000 -> 2.6564406 | AD34: =AB34-V34 -> -579836.67 | AE34: =AC34-Y34 -> -4.6386934 | AF34: =AK34 -> TRK_112_2 | AG34: 112/18:29 | AH34: =X34*8/1000000 -> -7.0501119e-13 | AI34: =V34*8/1000000 -> 7.295134 | AJ34: 7.295134 | AK34: TRK_112_2 | AL34: 2025-112T18:44:01 | AM34: 0.23528 | AN34: 2 | AO34: 1.064274 | AP34: 0.828992 | AQ34: 7.295134
AB35: Pos – act is greater
P36: 097 01:06:28 | Q36: 096 16:35:01 | R36: 606263216 | S36: 7 | T36: C&DH #1 | U36: TT 14 | V36: PEPSSI_LVPS_POWER CDBOTH ON | W36: Turn ON PEPSSI | X36: K2PE_PEPSSI_POWERON_Macro_101_2025_096 | AA36: pbrprt | AB36: Act – pred | AC36: mbits
A37: pwr on => | L37: 96/16:35 | M37: 99/20:14 | O37: 113/10:49 | P37: 113_1 | Q37: =R36-20 -> 606263196 | R37: =((W37-U37*$V$23)/$V$10)+Q37 -> 6.0653598e+08 | S37: =R37-Q37 -> 272779.99 | T37: =S37*$V$10 -> 1324552.9 | U37: 1 | V37: =T37+U37*$V$23 -> 1521927.9 | W37: =Y37*1000000/8 -> 1521927.9 | X37: =W37-V37 -> -2.7753413e-07 | Y37: =AJ37 -> 12.175423 | AA37: 1614636 | AB37: =AA37-T37 -> 290083.12 | AC37: =(AB37/8)/1000000 -> 0.036260391 | AF37: =AK37 -> TRK_113_1 | AG37: 113/10:49 | AH37: =X37*8/1000000 -> -2.220273e-12 | AI37: =V37*8/1000000 -> 12.175423 | AJ37: 12.175423 | AK37: TRK_113_1 | AL37: 2025-113T11:04:01 | AM37: 0.23605 | AN37: 6 | AO37: 1.619627 | AP37: 1.383571 | AQ37: 12.175423
L38: =M37 -> 99/20:14 | M38: 104/11:33 | O38: 114/04:39 | P38: 114_1 | Q38: =R37-1 -> 6.0653597e+08 | R38: =((W38-U38*$V$23)/$V$10)+Q38 -> 6.0693725e+08 | S38: =R38-Q38 -> 401274.55 | T38: =S38*$V$10 -> 1948491 | U38: 0 | V38: =T38+U38*$V$23 -> 1948491 | W38: =Y38*1000000/8 -> 1948491 | X38: =W38-V38 -> -2.6449561e-07 | Y38: =AJ38 -> 15.587928 | AA38: 2057144 | AB38: =AA38-T38 -> 108653 | AC38: =(AB38/8)/1000000 -> 0.013581625 | AF38: =AK38 -> TRK_114_1_ | AG38: 114/04:39 | AH38: =X38*8/1000000 -> -2.1159649e-12 | AI38: =V38*8/1000000 -> 15.587928 | AJ38: 15.587928 | AK38: TRK_114_1_ | AL38: 2025-114T04:54:01 | AM38: 0.40828 | AN38: 6 | AO38: 2.179641 | AP38: 1.771355 | AQ38: 15.587928
L39: =M38 -> 104/11:33 | M39: 107/02:56 | O39: 115/00:44 | P39: 115_1 | Q39: =R38-1 -> 6.0693725e+08 | R39: =((W39-U39*$V$23)/$V$10)+Q39 -> 6.0716573e+08 | S39: =R39-Q39 -> 228485.52 | T39: =S39*$V$10 -> 1109469.7 | U39: 0 | V39: =T39+U39*$V$23 -> 1109469.7 | W39: =Y39*1000000/8 -> 1109469.8 | X39: =W39-V39 -> 2.4074689e-07 | Y39: =AJ39 -> 8.875758 | AA39: 1157806 | AB39: =AA39-T39 -> 48336.25 | AC39: =(AB39/8)/1000000 -> 0.0060420313 | AF39: =AK39 -> TRK_115_1 | AG39: 115/00:44 | AH39: =X39*8/1000000 -> 1.9259751e-12 | AI39: =V39*8/1000000 -> 8.875758 | AJ39: 8.875758 | AK39: TRK_115_1 | AL39: 2025-115T00:59:01 | AM39: 0.25274 | AN39: 0 | AO39: 1.261349 | AP39: 1.008609 | AQ39: 8.875758
AJ40: =SUM(AJ37:AJ39) -> 36.639109
L41: 106/15:30 | M41: 107/14:27 | O41: 118/04:45 | P41: 118_1 | Q41: =R34-1 -> 6.0712335e+08 | R41: =((W41)/$V$9)+Q41 -> 6.0716481e+08 | S41: =R41-Q41 -> 41459.719 | T41: =S41*$V$9 -> 158376.13 | U41: 0 | V41: =T41+U41*$V$23 -> 158376.13 | W41: =Y41*1000000/8 -> 158376.12 | X41: =W41-V41 -> -2.1932647e-07 | Y41: =AJ41 -> 1.267009 | AB41: =S41*$S$9 -> 57670.876 | AC41: =AB41*8/1000000 -> 0.46136701 | AD41: =AB41-V41 -> -100705.25 | AE41: =AC41-Y41 -> -0.80564199 | AF41: =AK41 -> TRK_118_1 | AG41: 118/04:45 | AH41: =X41*8/1000000 -> -1.7546117e-12 | AI41: =V41*8/1000000 -> 1.267009 | AJ41: 1.267009 | AK41: TRK_118_1 | AL41: 2025-118T05:00:01 | AM41: 0.65856 | AN41: 2 | AO41: 0.80254 | AP41: 0.143978 | AQ41: 1.267009
M42: 107/03:01 | Y42: =SUM(Y31:Y41) -> 69.607271 | AB42: =AC41+AC34+AC33+AC32+AC31 -> 16.32409
...

Sheet Sheet2
E11: pwr on | F11: pwr off | G11: data_type
E12: met1 | F12: met2
E13: met2 | F13: met3
E14: met4 | F14: met4

Sheet 2025_pb_2
M2: not played back swap | N2: 126 | O2: 159 | P2: =O2-N2 -> 33 | Q2: =P2*S6 -> 31.728378 | R2: RT2H => | S2: ='SWAP Data Volumns'!K108 -> 0.50566653
N3: 159 | O3: 181 | P3: =O3-N3 -> 22 | Q3: =P3*X6 -> 56.201821 | R3: RT1H=> | S3: ='SWAP Data Volumns'!K99 -> 0.80996711 | V3: =4.513307/V10 -> 0.92947581 | X3: =25/X6 -> 9.7861598
N4: 181 | O4: 218 | P4: =O4-N4 -> 37 | Q4: =P4*S6 -> 35.574242 | R4: RT30M => | S4: ='SWAP Data Volumns'!K90 -> 1.4028286 | W4: SWAP 2H | X4: ='SWAP Data Volumns'!K108 -> 0.50566653
L5: =66+90+23+164+28+5 -> 376 | M5: =16+18+66+90+23+164+33 -> 410 | Q5: =Q4+Q3+Q2 -> 123.50444 | R5: RT10M => | S5: ='SWAP Data Volumns'!K72 -> 3.695932
L6: =(51-44)*X6 -> 17.882397 | M6: =82+49+54+105+82+39 -> 411 | R6: Mbits/day | S6: 0.961466 | U6: Mbits/day | V6: =V9*8*86400/1000000 -> 2.640384 | W6: 2.546459 | X6: 2.5546282
L7: =(83-51)*X6 -> 81.748103 | M7: =87+161+205+666+18 -> 1137 | R7: Non-hibernatio | S7: RT = 30 MIN | U7: hibernation | V7: RT = 10 MIN | Z7: DT1 | AA7: DT2 | AB7: HSK3 | AC7: DT2 if 102 | AD7: DT3 | AE7: DT4
L8: =299+46+23+41 -> 409 | R8: swap gain by/s | S8: 14.778455 | T8: =T9*1.1 -> 0.40055257 | U8: swap gain by/s | V8: 14.778455 | W8: should be: | X8: latest: | Z8: N1 | AA8: N3 | AB8: Status | AC8: Buff Rates | AD8: N2 | AE8: Trig Assess | AF8: Mbits/d
N9: 125Mb/2.55Mb/d | O9: =125/X6 -> 48.930799 | Q9: 0.961466 | R9: swap bytes/s | S9: =S6*1000000/(8*86400) -> 1.3910098 | T9: =S9/V9 -> 0.3641387 | U9: swap bytes/s | V9: 3.82 | W9: =W6*1000000/(8*86400) -> 3.6841131 | X9: =X6*1000000/(8*86400) -> 3.695932 | Y9: total bps | Z9: bps | AA9: bps | AB9: bps | AC9: bps | AD9: bps | AE9: bps
N10: end of 25181 | O10: =347+49-365 -> 31 | S10: erroneously used in 96/118 | T10: MACRO 101 | U10: pepssi bytes/s | V10: =Y10/8 -> 4.8557552 | W10: w N2 + DT4 | X10: N1 = 120 | Y10: =SUM(Z10:AE10) -> 38.846042 | Z10: 16.566667 | AA10: 2.5244444 | AB10: 0.28444444 | AC10: 10.869792 | AD10: 5.8611111 | AE10: 2.7395833
M11: plus gain | N11: days pb 207 | O11: =(40-6)/X6 -> 13.309177 | S11: should have used for 96/118 | T11: MACRO 101 | U11: pepssi bytes/s | V11: =Y11/8 -> 4.5133073 | W11: w N2 no DT4 | X11: N1 = 120 | Y11: =SUM(Z11:AE11) -> 36.106458 | Z11: 16.566667 | AA11: 2.5244444 | AB11: 0.28444444 | AC11: 10.869792 | AD11: 5.8611111 | AF11: =Y11*86400/1000000 -> 3.119598
N12: =(83-45)*X6 -> 97.075872 | S12: 25159 | T12: MAC 103/110 | U12: pepssi bytes/s | V12: =Y12/8 -> 3.0903906 | W12: No N2/DT4 | X12: N1 = 180 | Y12: =SUM(Z12:AE12) -> 24.723125 | Z12: 11.044444 | AA12: 2.5244444 | AB12: 0.28444444 | AC12: 10.869792 | AF12: =Y12*86400/1000000 -> 2.136078
P13: ?? | S13: 25139 | T13: MACRO 101 | U13: pepssi bytes/s | V13: =Y13/8 -> 3.7806684 | W13: No N2/DT4 | X13: N1 = 120 | Y13: =SUM(Z13:AE13) -> 30.245347 | Z13: 16.566667 | AA13: 2.5244444 | AB13: 0.28444444 | AC13: 10.869792 | AF13: =Y13*86400/1000000 -> 2.613198
S14: 25159 | T14: MAC 103/110 | U14: pepssi bytes/s | V14: =Y14/8 -> 0.34244792 | W14: DT4 | X14: N1 = 180 | Y14: =SUM(Z14:AE14) -> 2.7395833 | AE14: 2.7395833 | AF14: =Y14*86400/1000000 -> 0.2367 | AG14: =AF14*21 -> 4.9707
S15: 25159 no macros | T15: ‘survey’ only | U15: pepssi bytes/s | V15: =Y15/8 -> 1.7316667 | W15: N1/N3/St | X15: N1 = 180 | Y15: =SUM(Z15:AE15) -> 13.853333 | Z15: 11.044444 | AA15: 2.5244444 | AB15: 0.28444444 | AF15: =Y15*86400/1000000 -> 1.196928
Q16: NO ==> not 120 | S16: 25181 no macros | T16: ‘survey’ only | U16: pepssi bytes/s | V16: =Y16/8 -> 2.4219444 | W16: N1/N3/St | X16: N1 = 120 | Y16: =SUM(Z16:AE16) -> 19.375556 | Z16: 16.566667 | AA16: 2.5244444 | AB16: 0.28444444 | AF16: =Y16*86400/1000000 -> 1.674048
Q17: n1/n2/st/ta | S17: 25181 | T17: MAC 103/105 | U17: pepssi bytes/s | V17: =Y17/8 -> 2.1248785 | W17: No N3/BuffR | X17: N1 = 180 | Y17: =SUM(Z17:AE17) -> 16.999028 | Z17: 11.044444 | AB17: 0.28444444 | AD17: 2.9305556 | AE17: 2.7395833 | AF17: =Y17*86400/1000000 -> 1.468716
Q18: n3/br | S18: 25181 | T18: MAC 103/105 | U18: pepssi bytes/s | V18: =Y18/8 -> 1.6742795 | W18: only N3/Buff | X18: N1 = 180 | Y18: =SUM(Z18:AE18) -> 13.394236 | AA18: 2.5244444 | AC18: 10.869792 | AF18: =Y18*86400/1000000 -> 1.157262
S19: 25181 | T19: MAC 103/105 | U19: pepssi bytes/s | V19: =Y19/8 -> 3.799158 | W19: all | X19: N1 = 180 | Y19: =SUM(Z19:AE19) -> 30.393264 | Z19: 11.044444 | AA19: 2.5244444 | AB19: 0.28444444 | AC19: 10.869792 | AD19: 2.9305556 | AE19: 2.7395833 | AF19: =Y19*86400/1000000 -> 2.625978
S20: 25159 | T20: MAC 103/110 | U20: pepssi bytes/s | V20: =Y20/8 -> 52.75 | W20: N2 only | X20: N1 = 180 | Y20: =SUM(Z20:AE20) -> 422 | AD20: 422 | AF20: =Y20*86400/1000000 -> 36.4608
Q21: n1/hsk3/n2,TA | T21: 25207 MAC 104/105 | U21: pepssi bytes/s | V21: =Y21/8 -> 1.7889844 | W21: N1/N2/TA/St | X21: N1=300 | Y21: =SUM(Z21:AE21) -> 14.311875 | Z21: 5.5222222 | AB21: 0.28444444 | AD21: 4.3958333 | AE21: 4.109375 | AF21: =Y21*86400/1000000 -> 1.236546
Q22: n3/br | T22: 26179 MAC 104/105 | U22: pepssi bytes/s | V22: =Y22/8 -> 4.5625304 | W22: n3/br | X22: N1 = 360 | Y22: =SUM(Z22:AE22) -> 36.500243 | AA22: 20.195556 | AC22: 16.304688 | AF22: =Y22*86400/1000000 -> 3.153621
Q23: U/D of v12 | S23: 25159 | T23: MAC 103/110 | U23: pepssi bytes/s | V23: =Y23/8 -> 3.2851736 | W23: No N2/DT4 | X23: N1 = 180 | Y23: =SUM(Z23:AE23) -> 26.281389 | Z23: 11.044444 | AA23: 2.765 | AB23: 0.28444444 | AC23: 12.1875 | AF23: =Y23*86400/1000000 -> 2.270712
Q24: U/D of v15 | S24: 25159 no macros | T24: ‘survey’ only | U24: pepssi bytes/s | V24: =Y24/8 -> 1.7617361 | W24: N1/N3/St | X24: N1 = 180 | Y24: =SUM(Z24:AE24) -> 14.093889 | Z24: 11.044444 | AA24: 2.765 | AB24: 0.28444444 | AF24: =Y24*86400/1000000 -> 1.217712
Q25: U/D of v14 | S25: 25159 | T25: MAC 103/110 | U25: pepssi bytes/s | V25: =Y25/8 -> 0.3671875 | W25: DT4 | X25: N1 = 180 | Y25: =SUM(Z25:AE25) -> 2.9375 | AE25: 2.9375 | AF25: =Y25*86400/1000000 -> 0.2538
Q26: U/D of v17 | R26: n1/n2/st/ta | S26: 25181 | T26: MAC 103/105 | U26: pepssi bytes/s | V26: =Y26/8 -> 2.1681366 | W26: No N3/BuffR | X26: N1 = 180 | Y26: =SUM(Z26:AE26) -> 17.345093 | Z26: 11.044444 | AB26: 0.28444444 | AD26: 3.0787037 | AE26: 2.9375 | AF26: =Y26*86400/1000000 -> 1.498616
Q27: U/D of v20 | S27: 25159 | T27: MAC 103/110 | U27: pepssi bytes/s | V27: =Y27/8 -> 55.416667 | W27: N2 only | X27: N1 = 180 | Y27: =SUM(Z27:AE27) -> 443.33333 | AD27: 443.33333 | AF27: =Y27*86400/1000000 -> 38.304
Q28: U/D of v18 | S28: 25181 | T28: MAC 103/105 | U28: pepssi bytes/s | V28: =Y28/8 -> 1.8690625 | W28: only N3/Buff | X28: N1 = 180 | Y28: =SUM(Z28:AE28) -> 14.9525 | AA28: 2.765 | AC28: 12.1875 | AF28: =Y28*86400/1000000 -> 1.291896
N29: =O29/1000000 -> 0.0091461812 | O29: =Y29*180 -> 9146.1812 | Q29: n1/n2/n3/st/ta | T29: 26179 MAC 104/105 | U29: pepssi bytes/s | V29: =Y29/8 -> 6.3515148 | W29: n1/n2/n3/st/ta | X29: N1 = 360 | Y29: =SUM(Z29:AE29) -> 50.812118 | Z29: 5.5222222 | AA29: 20.195556 | AB29: 0.28444444 | AC29: 16.304688 | AD29: 4.3958333 | AE29: 4.109375 | AF29: =Y29*86400/1000000 -> 4.390167
Q30: n1/n2/n3/st/ta | S30: 26201 | T30: MAC 103/109 | U30: pepssi bytes/s | V30: =Y30/8 -> 4.9404774 | W30: n1/n2/n3/st/ta | X30: 360/7200/1800 | Y30: =SUM(Z30:AE30) -> 39.523819 | Z30: 5.5222222 | AA30: 2.5244444 | AB30: 0.28444444 | AC30: 10.869792 | AD30: 17.583333 | AE30: 2.7395833 | AF30: =Y30*86400/1000000 -> 3.414858
Q31: ta only | S31: 26179 | T31: MAC 103/109 | U31: pepssi bytes/s | V31: =Y31/8 -> 0.34244792 | W31: n1/n2/n3/st/ta | X31: 360/7200/1800 | Y31: =SUM(Z31:AE31) -> 2.7395833 | AE31: 2.7395833 | AF31: =Y31*86400/1000000 -> 0.2367
Z32: DT1 | AA32: DT2 | AB32: HSK3 | AC32: DT2 if 102 | AD32: DT3 | AE32: DT4
U33: pwron bytes | V33: 197375 | Z33: N1 | AA33: N3 | AB33: Status | AC33: Buff Rates | AD33: N2 | AE33: Trig Assess | AF33: Mbits/d
P34: 097 00:46:28 | Q34: 096 16:15:01 | R34: 606262016 | S34: 8 | T34: C&DH #1 | U34: TT 12 | V34: SWAP_LVPS_POWER CDBOTH ON | W34: Turn ON SWAP | X34: K1SW_A4_SWAP_Daily_ON_096_1_power_on
O35: 25096 gain test | P35: 099 11:31:17 | Q35: 099 03:00:01 | R35: 606473516 | S35: 7 | T35: C&DH #1 | U35: TT 77 | V35: SWAP_LVPS_POWER CDBOTH ON | W35: Turn ON SWAP | X35: K1SW_A4_SWAP_GAIN_099_1
P36: 099 13:21:29 | Q36: 099 04:50:13 | R36: 606480128 | S36: 0 | T36: SWAP #1 | U36: TT 086 | V36: SWAP_TLM_HK_RATE 1H MACRO=EXEC | X36: K1SW_A4_SWAP_OFF_099__A4
P37: =R36-R35 -> 6612 | R37: 589335049 | S37: 589362052 | T37: =S37-R37 -> 27003 | U37: 110684 | V37: =U37/T37 -> 4.098952
M38: =(20+16/24)*38.9*86400/1000000 -> 69.45984 | P38: 099 13:54:49 | Q38: 099 05:23:33 | R38: 606482128 | S38: 1 | T38: C&DH #1 | U38: TT 87 | V38: SSR_LO_RCRD_SYNC SWAP_DT1 | X38: K1SW_A4_Refresh_All_099 | AD38: =11000000/500 -> 22000 | AE38: =AD38/3600 -> 6.1111111 | AG38: remaining
P39: 25096 | U39: =V33 -> 197375 | W39: Mbits/sec | X39: 2.70622e-05 | AB39: bytes using corrected rates | AE39: =11000000/500 -> 22000 | AF39: =AE39/3600 -> 6.1111111 | AH39: on track | AI39: Mbit dl
P40: track | Q40: start met | R40: end met | S40: seconds | T40: calculated bytes | U40: power ons | V40: total calc bytes | W40: bytes avail | X40: difference | AA40: pb report | AB40: calculated | AC40: actual Mbits | AD40: delta | AE40: delta | AH40: rel to S | AJ40: =AJ41+AJ43+AJ44 -> 31.701153
L41: 96/16:15 | M41: 99/03:01 | N41: pwron to gain | O41: 111/08:19 | P41: 111_1 | Q41: =R34-20 -> 606261996 | R41: =R35 -> 606473516 | S41: =R41-Q41 -> 211520 | T41: =S41*$V$9 -> 808006.4 | U41: 0 | V41: =T41+U41*$V$33 -> 808006.4 | W41: =Y41*1000000/8 -> 1085211.8 | X41: =W41-V41 -> 277205.35 | Y41: =8.681694 -> 8.681694 | AA41: 344216 | AB41: =S41*$S$9 -> 294226.4 | AC41: =AB41*8/1000000 -> 2.3538112 | AD41: =AB41+AB42 -> 1088101.4 | AE41: =AC41+AC42 -> 8.7048112 | AF41: TRK_111_1 | AG41: 111/08:19 | AH41: =X41*8/1000000 -> 2.2176428 | AI41: =V41*8/1000000 -> 6.4640512 | AJ41: 8.681694 | AK41: TRK_111_1 | AL41: 2025-111T08:34:01 | AM41: 0.80021 | AN41: 6 | AO41: 1.786772 | AP41: 0.986556 | AQ41: 8.681694
...

Sheet calculations
B3: alice spinning pixellist
A4: =G9+G6 -> 222.648 | B4: alice spinning pixellist
A5: clusters | C5: start | D5: end | F5: raw dlv | G5: dldv | J5: calculated end
A6: 27 | B6: TRK_205_1 | C6: 645951158 | D6: 645951767 | F6: 26.764 | G6: 28.626
G7: =G6*1000000/8 -> 3578250
C8: start | D8: end | H8: 208_1 dldv
A9: 183 | B9: TRK_207_1 | C9: 645951790 | D9: 645955455 | E9: =D9-C9 -> 3665 | F9: 174.619 | G9: 194.022 | H9: =58.7-G6 -> 30.074 | I9: =H9/G9 -> 0.15500304 | J9: =C9+I9*E9 -> 6.4595236e+08 | K9: end time to play back 30.074 Mbits
C10: original acquisition start | D10: and en | G10: =G9*1000000/8 -> 24252750 | H10: =H9*1000000/8 -> 3759250
G13: 645952358

Sheet SWAP Data Volumns
B2: Packet Names | C2: APID | D2: Size (bytes) | E2: Size (bits) | F2: Number of Packets in Set | H2: Housekeeping (0x580) Rates Settings | I2: Data Rate [Hz] | J2: Time Interval [s] | L2: RT (0x584), SM (0x585), & HIST(0x586/7) Rates | M2: Data Rate [hz] | N2: Time Interval [s]
B3: Housekeeping | C3: 0x580 | D3: 75 | E3: =D3*8 -> 600 | F3: 1 | H3: NEVER | I3: 0 | L3: NEVER | M3: 0 | N3: 0
B4: Message | C4: 0x582 | D4: 33 | E4: =D4*8 -> 264 | F4: Variable | H4: 24H | I4: =1/(24*60*60) -> 1.1574074e-05 | J4: 86400 | L4: 24H | M4: =1/N4 -> 1.1574074e-05 | N4: 86400
B5: Realtime Science | C5: 0x584 | D5: 35 | E5: =D5*8 -> 280 | F5: 64 | H5: 12H | I5: =1/(12*60*60) -> 2.3148148e-05 | J5: 43200 | L5: 12H | M5: =1/N5 -> 2.3148148e-05 | N5: 43200
B6: Summary | C6: 0x585 | D6: 87 | E6: =D6*8 -> 696 | F6: 1 | H6: 6H | I6: =1/(6*60*60) -> 4.6296296e-05 | J6: 21600 | L6: 6H | M6: =1/N6 -> 4.6227811e-05 | N6: 21632
B7: Histogram 0 | C7: 0x586 | D7: 216 | E7: =D7*8 -> 1728 | F7: 1 | H7: 3H | I7: =1/(3*60*60) -> 9.2592593e-05 | J7: 10800 | L7: 3H | M7: =1/N7 -> 9.2455621e-05 | N7: 10816
B8: Histogram 1 | C8: 0x587 | D8: 204 | E8: =D8*8 -> 1632 | F8: 63 | H8: 2H | I8: =1/(2*60*60) -> 0.00013888889 | J8: 7200 | L8: 2H | M8: =1/N8 -> 0.00013827434 | N8: 7232
H9: 1H | I9: =1/(60*60) -> 0.00027777778 | J9: 3600 | L9: 1H | M9: =1/N9 -> 0.00027412281 | N9: 3648
H10: 30M | I10: =1/(30*60) -> 0.00055555556 | J10: 1800 | L10: 30M | M10: =1/N10 -> 0.0005387931 | N10: =1856 -> 1856
H11: 20M | I11: =1/(20*60) -> 0.00083333333 | J11: =1200 -> 1200 | L11: 20M | M11: =1/N11 -> 0.00078125 | N11: =20*64 -> 1280
H12: 10M | I12: =1/(10*60) -> 0.0016666667 | J12: 600 | L12: 10M | M12: =1/N12 -> 0.0015625 | N12: =10*64 -> 640
H13: 5M | I13: =1/(5*60) -> 0.0033333333 | J13: 300 | L13: 5M | M13: =1/N13 -> 0.003125 | N13: =5*64 -> 320
H14: 2M | I14: =1/(2*60) -> 0.0083333333 | J14: 120 | L14: 2M | M14: =1/N14 -> 0.0078125 | N14: =2*64 -> 128
H15: 64S | I15: =1/64 -> 0.015625 | J15: 64 | L15: 64S | M15: =1/N15 -> 0.015625 | N15: 64
H16: 32S | I16: =1/32 -> 0.03125 | J16: 32
H17: 16S | I17: =1/16 -> 0.0625 | J17: 16
H18: 8S | I18: =1/8 -> 0.125 | J18: 8
H19: 4S | I19: =1/4 -> 0.25 | J19: 4
H20: 2S | I20: =1/2 -> 0.5 | J20: 2
H21: 1S | I21: =1 -> 1 | J21: 1
B25: 0x584 at 1min (64sec) with 0x580 1H; 0x585 1H; 0x586/7 never No Histograms
C26: APID | D26: Bits/Packet | E26: Rate Mode | F26: Packets/Sec | G26: Bits/Second | H26: Interval [sec] | I26: Total [Mbits]
B27: HK | C27: 0x580 | D27: =$E$3 -> 600 | E27: 1H | F27: =$I$9*$F$3 -> 0.00027777778 | G27: =D27*F27 -> 0.16666667 | H27: 86400 | I27: =G27*H27/1000000 -> 0.0144
B28: RTSCI | C28: 0x584 | D28: =$E$5 -> 280 | E28: 64S | F28: =$M$15*$F$5 -> 1 | G28: =D28*F28 -> 280 | H28: 86400 | I28: =G28*H28/1000000 -> 24.192
B29: Summary | C29: 0x585 | D29: =$E$6 -> 696 | E29: 1H | F29: =$M$9*$F$6 -> 0.00027412281 | G29: =D29*F29 -> 0.19078947 | H29: 86400 | I29: =G29*H29/1000000 -> 0.016484211
B30: Histogram 0 | C30: 0x586 | D30: =$E$7 -> 1728 | E30: Never | F30: 0 | G30: =D30*F30 -> 0 | H30: 0 | I30: =G30*H30/1000000 -> 0 | J30: If we use this combination, we will have to write a code ceate the histograms from the 0x584 data. This is possible because with 0x584 set to 64 seconds we are downloadding all the sweeps performed back to back.
B31: Histogram 1 | C31: 0x587 | D31: =$E$8 -> 1632 | E31: Never | F31: 0 | G31: =D31*F31 -> 0 | H31: 0 | I31: =G31*H31/1000000 -> 0
H32: Total: | I32: =SUM(I27:I31) -> 24.222884
B38: 0x584 at 1min (64sec) with 0x580 1H; 0x585 1H; 0x586/7 24H
C39: APID | D39: Bits/Packet | E39: Rate Mode | F39: Packets/Sec | G39: Bits/Second | H39: Interval [sec] | I39: Total [Mbits]
B40: HK | C40: 0x580 | D40: =$E$3 -> 600 | E40: 1H | F40: =$I$9*$F$3 -> 0.00027777778 | G40: =D40*F40 -> 0.16666667 | H40: 86400 | I40: =G40*H40/1000000 -> 0.0144
B41: RTSCI | C41: 0x584 | D41: =$E$5 -> 280 | E41: 64S | F41: =$M$15*$F$5 -> 1 | G41: =D41*F41 -> 280 | H41: 86400 | I41: =G41*H41/1000000 -> 24.192
B42: Summary | C42: 0x585 | D42: =$E$6 -> 696 | E42: 1H | F42: =$M$9*$F$6 -> 0.00027412281 | G42: =D42*F42 -> 0.19078947 | H42: 86400 | I42: =G42*H42/1000000 -> 0.016484211
B43: Histogram 0 | C43: 0x586 | D43: =$E$7 -> 1728 | E43: 24H | F43: =$M$4*$F$7 -> 1.1574074e-05 | G43: =D43*F43 -> 0.02 | H43: 86400 | I43: =G43*H43/1000000 -> 0.001728 | J43: We could turn off the histograms 0x586 and 0x587 because with this option the 0x584 is performing continuous sweep such that we could construct histograms on the ground from the 0x584 packets by writing a computer program.
B44: Histogram 1 | C44: 0x587 | D44: =$E$8 -> 1632 | E44: 24H | F44: =$M$4*$F$8 -> 0.00072916667 | G44: =D44*F44 -> 1.19 | H44: 86400 | I44: =G44*H44/1000000 -> 0.102816
H45: Total: | I45: =SUM(I40:I44) -> 24.327428 | J45: =I45*1000000/86400 -> 281.56746 | K45: =J45/8 -> 35.195932
J46: bps | K46: bytes/s
B47: 0x584 at 2min with 0x580 1H; 0x585 1H; 0x586/7 24H
C48: APID | D48: Bits/Packet | E48: Rate Mode | F48: Packets/Sec | G48: Bits/Second | H48: Interval [sec] | I48: Total [Mbits]
B49: HK | C49: 0x580 | D49: =$E$3 -> 600 | E49: 1H | F49: =$I$9*$F$3 -> 0.00027777778 | G49: =D49*F49 -> 0.16666667 | H49: 86400 | I49: =G49*H49/1000000 -> 0.0144
...

Sheet Overview 2025
E1: SWAP | N1: PEPSSI
D3: Playback | E3: Playback | F3: Approximate | G3: Acquisition | H3: Acq Rate | I3: Acq Rate | K3: Played Back | M3: Playback | N3: Playback | O3: Approximate | P3: Played Back | Q3: Played Back
D4: Start | E4: End | F4: Days | G4: Mode | H4: (bps) | I4: (Mbits/d) | J4: Mbits | K4: Cum Total | M4: Start | N4: End | O4: Days | P4: Mbits | Q4: Cum Total
B5: 25096 | C5: Post-hib | D5: 2025-96/06:15 | E5: 107/03:02 | F5: =107-96 -> 11 | G5: RT30 | H5: 16.32 | I5: 0.9696 | J5: 16.32 | K5: =H5 -> 16.32 | L5: Post-hib | M5: 96/16:35 | N5: 107/02:56 | O5: =107-96 -> 11 | P5: 36.6 | Q5: =P5 -> 36.6 | R5: N1, N2, Status, Buff Rates
L6: Post-hib Mops | M6: 2025-96 | N6: 2025-118 | O6: 21 | R6: Trig Assessment (post-hibernation)
B7: 25118 | C7: Post-hib | D7: 2025-107/03:02 | E7: 126/03:18 | F7: =126-107 -> 19 | G7: RT30 | H7: 17.6 | I7: 0.9696 | J7: 17.6 | K7: =H7+H5 -> 33.92 | L7: Post-hib | M7: 107/02:56 | N7: 119/07:51 | O7: =116-107 -> 9 | P7: 41 | Q7: =P7+Q5 -> 77.6 | R7: N1, N2, Status, Buff Rates
L8: Post-hib Mops | M8: 2025-118 | N8: 2025-139 | O8: 172 | P8: =5227688*8/1000000 -> 41.821504 | Q8: =Q7+P8 -> 119.4215 | R8: Trig Assessment (post-hibernation)
L9: Hibernation Mops pb | R9: Trig Assessment (hibernation)
B10: 25139 | C10: hibernation | D10: 2024-276/01:32 | E10: 302/14:44 | F10: =302-276 -> 26 | G10: RT10 | H10: 64.4 | I10: 2.5546 | J10: 64.4 | K10: =K7+H10 -> 98.32 | L10: Post-hib | M10: 119/07:51 | N10: 135/13:16 | O10: =135-119 -> 16 | P10: 56.5 | Q10: =Q8+P10 -> 175.9215 | R10: DT1, DT2,HSK, N2
P11: =P10+P7+P5 -> 134.1
A12: 178 | B12: 25159 | C12: hibernation | D12: 2024-302/14:44 | E12: 338/00:07 | F12: =338-302 -> 36 | G12: RT10 | H12: 90.4 | I12: 2.5546 | J12: 90.4 | K12: =K10+H12 -> 188.72 | L12: Post-hib | M12: 135/13:16 | N12: 178/19:30 | O12: =178-135 -> 43 | P12: 105.5 | Q12: =Q10+P12 -> 281.4215 | R12: DT1, DT2,HSK (NO N2 or DT4)
A13: =90.4+105.5 -> 195.9
A14: =A13-A12 -> 17.9
A15: =486-A14 -> 468.1 | H15: =H17+H10 -> 436.18301
B16: REMAINING:
C17: hibernation | D17: 2024-338/00:07 | E17: 2025-083/08:02 | F17: =83+365-302 -> 146 | G17: RT10 | H17: =(F17*86400*8*'2025_pb'!W9)/1000000 -> 371.78301 | I17: 2.5546 | J17: =I17*F17 -> 372.9716 | K17: =H17 -> 371.78301 | L17: Hib remain | M17: 24/276 | N17: 2025/83 | O17: =83+365-276 -> 172 | P17: =241+379 -> 620 | Q17: =P17 -> 620
C18: Post hib 2025-126 to 159 | D18: 126/03:18 | E18: ~doy 219 | F18: =219-126 -> 93 | H18: =F18*86400*8*'2025_pb'!S9/1000000 -> 89.416338 | J18: =H18*86400*8*'2025_pb'!T9/1000000 -> 22.505437 | K18: =K17+H18 -> 461.19935 | L18: Post-hib remain | N18: ~doy217
B19: post hib total | D19: 96 | E19: 219 | F19: =E19-D19 -> 123 | I19: 0.9696 | J19: =I19*F19 -> 119.2608
M21: =296-189 -> 107
D24: total | E24: Pb 96/118 | F24: Pb 139/159 | G24: remaining | J24: functional | K24: 150 | L24: 160 | O24: post hib 96 – 135 | P24: 134
C25: swp post hib | D25: 274 | E25: =16.32+17.6 -> 33.92 | G25: =D25-E25 -> 240.08 | J25: swap hib remain | K25: 372 | L25: 284 | O25: hib trig mops | P25: 42
C26: swap hib | D26: 439 | F26: =64.4+90.4 -> 154.8 | G26: =D26-F26 -> 284.2 | J26: swap post hib | K26: 89 | L26: 240 | O26: post hib trig | P26: 15
J27: pep hib | K27: 620 | L27: 536 | O27: post hib survey | P27: 105
C28: trig ass posthib 96 – 159 | D28: =(159-96)*0.24 -> 15.12 | J28: peps post hib | K28: 461 | L28: =59.4+36.6 -> 96 | M28: surv+buf+tr post | P28: =SUM(P24:P27) -> 296
K29: =SUM(K24:K28) -> 1692 | L29: =6.3+10.5 -> 16.8 | M29: n2 post
O30: hib n2 | P30: 87
O31: hib survey + buff | P31: 449
I32: =96+203+160 -> 459 | P32: =P31+P30 -> 536
B33: PB DLDV | D33: SWAP
A34: 25159 | B34: 178
A35: 25181 | B35: 386
A36: 25207 | B36: 100
B37: 664

Sheet Sheet37
E14: Hibernation
D15: HSK3
D17: DT1
D19: DT2
D21: DT3
D23: DT4 | E23: DT4 | G23: DT3 | H23: DT2 | I23: DT1 | J23: HSK3
J24: 607591634 607607834
E25: 590222814 606280735 | J25: 606263976 606264328
C26: 606356633 606411235 | E26: 606280733 606323935 | G26: 606263196 606535598
E27: 606323933 606356635 | G27: 606535597 606936315
E28: 606356633 606411235 | G28: 606936314 607164482 | I28: 606535597 606936315
E29: 606411233 606458035
E30: 606411233 606458035 | G30: 607164481 607931342
E31: 606557033 606583435 | G31: 607961196 608218979
E32: 606583433 606641035 | G32: 608218978 608536142
E33: 607224593 607484095 | G33: 608566037 608594683
E34: 606641033 606708895 | G34: 608594682 608803371
E35: 606708893 606884995 | G35: 608803370 608964552
E36: 606884993 606986995 | G36: 608964551 609237996
E37: 606986993 607046095 | G37: 609237995 609416427
E38: 607046093 607101595 | G38: 609416426 609620873
E39: 607101593 607147795 | G39: Pep 1 | I39: pep2
E40: 607147793 607224595 | G40: 609410289 609411609 | I40: 609250141 609251866
E41: 607484093 607530295 | I41: 609265620 609267207
E42: 607530293 607588795
E43: 607588793 607653295 | G43: 609625453 609911822
E44: 607653293 607712095 | G44: 609953285 610156755
E45: 607712093 607776295 | G45: 610156754 610410247
E46: 607776293 607848595 | G46: 610457872 610697909
E47: 608059553 608085955 | G47: 610650282 610784848
E48: 608085953 608122255 | G48: 610650282 610784848
E49: 608122253 608192155 | G49: 610784847 611216550
E50: 608252753 608288155 | G50: 611216549 611398759
D51: pep4 | E51: 608288153 608401255 | G51: 611398758 611652251
E52: 608401253 608428555 | G52: 611652250 611744042
E53: 600424745 606280735 | G53: 611744556 611851611
E54: 608122253 608192155 | G54: 611851610 612349039
E55: 608192153 608252755 | G55: 612349038 612647515
E56: 608428553 608477155
E57: 608477153 608694655
...

Sheet swap_rates
G2: tim bef gain | H2: time aft gain | I2: non gain time | J2: bytes non gain | K2: Mbits non gain | L2: bytes of gain | M2: Mbits of gain
G3: =G6-G5 -> 36245 | H3: =H5-G7 -> 18955 | I3: =H3+G3 -> 55200 | J3: =I3*3.82 -> 210864 | K3: =J3*8/1000000 -> 1.686912 | L3: =E18-J3 -> 698011 | M3: =F18-K3 -> 5.584088
G4: st pb 79_1 | H4: end pb 79_1
G5: =H18 -> 573130071 | H5: =I18 -> 573191571
E6: 079 23:08:52 | F6: 079 15:00:00 | G6: 573166316 | H6: 8 | I6: C&DH #1 | J6: TT 38 | K6: SWAP_LVPS_POWER CDBOTH ON | L6: Turn ON SWAP | M6: K1SW_A4_SWAP_GAIN_079_1
D7: 24078 gain test | E7: 080 00:53:51 | F7: 079 16:45:00 | G7: 573172616 | H7: 7 | I7: C&DH #1 | J7: TT 45 | K7: SWAP_LVPS_POWER CDBOTH ON | L7: Turn ON SWAP | M7: K1SW_A4_SWAP_Daily_ON_079_1_endGain
G8: =G7-G6 -> 6300
D11: 25096 gain test | E11: 099 11:31:17 | F11: 099 03:00:01 | G11: 606473516 | H11: 7 | I11: C&DH #1 | J11: TT 77 | K11: SWAP_LVPS_POWER CDBOTH ON | L11: Turn ON SWAP | M11: K1SW_A4_SWAP_GAIN_099_1
E12: 099 13:21:29 | F12: 099 04:50:13 | G12: 606480128 | H12: 0 | I12: SWAP #1 | J12: TT 086 | K12: SWAP_TLM_HK_RATE 1H MACRO=EXEC | M12: K1SW_A4_SWAP_OFF_099__A4
D15: Bytes / sec | E15: bytes | F15: Mbits | J15: sec
D16: =E16/J16 -> 3.7935055 | E16: =(F16*1000000/8) -> 219625 | F16: 1.757 | G16: 24078 | H16: 573044876 | I16: 573102771 | J16: =I16-H16 -> 57895 | K16: =J16*$R$689 -> 0 | L16: 1.7217
D17: =E17/J17 -> 4.0521978 | E17: =(F17*1000000/8) -> 110625 | F17: 0.885 | G17: 078_1 | H17: =I16 -> 573102771 | I17: 573130071 | J17: =I17-H17 -> 27300 | K17: =J17*$R$689 -> 0 | L17: 908890
B18: =D18/D23 -> 0 | C18: gain test | E18: =(F18*1000000/8) -> 908875 | F18: 7.271 | G18: 079_1 | H18: =I17 -> 573130071 | I18: 573191571 | J18: =I18-H18 -> 61500 | K18: =J18*$R$689 -> 0 | L18: 908890
B19: x normal rate | D19: =E19/J19 -> 3.8722222 | E19: =(F19*1000000/8) -> 174250 | F19: 1.394 | G19: 079_2 | H19: =I18 -> 573191571 | I19: 573236571 | J19: =I19-H19 -> 45000 | K19: =J19*$R$689 -> 0 | L19: 908890
D20: =E20/J20 -> 3.755008 | E20: =(F20*1000000/8) -> 468625 | F20: 3.749 | G20: 080_1 | H20: =I19 -> 573236571 | I20: 573361371 | J20: =I20-H20 -> 124800 | K20: =J20*$R$689 -> 0 | L20: 908890
D21: =E21/J21 -> 3.7729167 | E21: =(F21*1000000/8) -> 226375 | F21: 1.811 | G21: 081_1 | H21: =I20 -> 573361371 | I21: 573421371 | J21: =I21-H21 -> 60000 | K21: =J21*$R$689 -> 0 | L21: 908890
D22: =E22/J22 -> 3.8367052 | E22: =(F22*1000000/8) -> 199125 | F22: 1.593 | G22: 082_1 | H22: =I21 -> 573421371 | I22: 573473271 | J22: =I22-H22 -> 51900 | K22: =J22*$R$689 -> 0 | L22: 908890
D23: =SUM(D19:D22)/4 -> 3.809213
D25: =E25/J25 -> 3.9256198 | E25: =(F25*1000000/8) -> 140125 | F25: 1.121 | G25: 24267 | H25: 589373156 | I25: 589408851 | J25: =I25-H25 -> 35695 | K25: =J25*$R$689 -> 0 | L25: 908890
D26: =E26/J26 -> 3.9579968 | E26: =(F26*1000000/8) -> 147000 | F26: 1.176 | G26: 267_2 | H26: 589408851 | I26: 589445991 | J26: =I26-H26 -> 37140 | K26: =J26*$R$689 -> 0 | L26: 908890
D27: =E27/J27 -> 3.791876 | E27: =(F27*1000000/8) -> 226375 | F27: 1.811 | G27: 268_1 | H27: 589445991 | I27: 589505691 | J27: =I27-H27 -> 59700 | K27: =J27*$R$689 -> 0 | L27: 908890
D28: =E28/J28 -> 3.7168561 | E28: =(F28*1000000/8) -> 294375 | F28: 2.355 | G28: 268_2 | H28: 589505691 | I28: 589584891 | J28: =I28-H28 -> 79200 | K28: =J28*$R$689 -> 0 | L28: 908890
D29: =E29/J29 -> 3.860252 | E29: =(F29*1000000/8) -> 337000 | F29: 2.696 | G29: 269_1 | H29: 589584891 | I29: 589672191 | J29: =I29-H29 -> 87300 | K29: =J29*$R$689 -> 0 | L29: 908890
D30: =E30/J30 -> 3.8356051 | E30: =(F30*1000000/8) -> 346125 | F30: 2.769 | G30: 270_1 | H30: 589672191 | I30: 589762431 | J30: =I30-H30 -> 90240 | K30: =J30*$R$689 -> 0 | L30: 908890
D31: =E31/J31 -> 3.7087579 | E31: =(F31*1000000/8) -> 305750 | F31: 2.446 | G31: 271_1 | H31: 589762431 | I31: 589844871 | J31: =I31-H31 -> 82440 | K31: =J31*$R$689 -> 0 | L31: 908890
D32: =SUM(D25:D31)/7 -> 3.8281377

Sheet swap_rates_2
G2: =H15 -> 573130071
E3: 079 23:08:52 | F3: 079 15:00:00 | G3: 573166316 | H3: 8 | I3: C&DH #1 | J3: TT 38 | K3: SWAP_LVPS_POWER CDBOTH ON | L3: Turn ON SWAP | M3: K1SW_A4_SWAP_GAIN_079_1
D4: 24078 gain test | E4: 080 00:53:51 | F4: 079 16:45:00 | G4: 573172616 | H4: 7 | I4: C&DH #1 | J4: TT 45 | K4: SWAP_LVPS_POWER CDBOTH ON | L4: Turn ON SWAP | M4: K1SW_A4_SWAP_Daily_ON_079_1_endGain
G5: =G4-G3 -> 6300 | H5: =K14-J14 -> -27300 | I5: =H5-G5 -> -33600 | J5: =I5*3.809313/1000000 -> -0.12799292 | K5: =H14-J5 -> 5.7310277e+08
G6: dur of gain test | H6: total pb period | I6: sec non gain | J6: Mbits of | K6: Mbits of gain
J7: non gain
D8: 25096 gain test | E8: 099 11:31:17 | F8: 099 03:00:01 | G8: 606473516 | H8: 7 | I8: C&DH #1 | J8: TT 77 | K8: SWAP_LVPS_POWER CDBOTH ON | L8: Turn ON SWAP | M8: K1SW_A4_SWAP_GAIN_099_1
E9: 099 13:21:29 | F9: 099 04:50:13 | G9: 606480128 | H9: 0 | I9: SWAP #1 | J9: TT 086 | K9: SWAP_TLM_HK_RATE 1H MACRO=EXEC | M9: K1SW_A4_SWAP_OFF_099__A4
D12: Bytes / sec | E12: bytes | F12: Mbits | J12: sec
D13: =E13/J13 -> 3.7935055 | E13: =(F13*1000000/8) -> 219625 | F13: 1.757 | G13: 24078 | H13: 573044876 | I13: 573102771 | J13: =I13-H13 -> 57895 | K13: =J13*$R$686 -> 0 | L13: 1.7217
D14: =E14/J14 -> 4.0521978 | E14: =(F14*1000000/8) -> 110625 | F14: 0.885 | G14: 078_1 | H14: =I13 -> 573102771 | I14: 573130071 | J14: =I14-H14 -> 27300 | K14: =J14*$R$686 -> 0 | L14: 908890
B15: =D15/D20 -> 3.879661 | C15: gain test | D15: =E15/J15 -> 14.778455 | E15: =(F15*1000000/8) -> 908875 | F15: 7.271 | G15: 079_1 | H15: =I14 -> 573130071 | I15: 573191571 | J15: =I15-H15 -> 61500 | K15: =J15*$R$686 -> 0 | L15: 908890
B16: x normal rate | D16: =E16/J16 -> 3.8722222 | E16: =(F16*1000000/8) -> 174250 | F16: 1.394 | G16: 079_2 | H16: =I15 -> 573191571 | I16: 573236571 | J16: =I16-H16 -> 45000 | K16: =J16*$R$686 -> 0 | L16: 908890
D17: =E17/J17 -> 3.755008 | E17: =(F17*1000000/8) -> 468625 | F17: 3.749 | G17: 080_1 | H17: =I16 -> 573236571 | I17: 573361371 | J17: =I17-H17 -> 124800 | K17: =J17*$R$686 -> 0 | L17: 908890
D18: =E18/J18 -> 3.7729167 | E18: =(F18*1000000/8) -> 226375 | F18: 1.811 | G18: 081_1 | H18: =I17 -> 573361371 | I18: 573421371 | J18: =I18-H18 -> 60000 | K18: =J18*$R$686 -> 0 | L18: 908890
D19: =E19/J19 -> 3.8367052 | E19: =(F19*1000000/8) -> 199125 | F19: 1.593 | G19: 082_1 | H19: =I18 -> 573421371 | I19: 573473271 | J19: =I19-H19 -> 51900 | K19: =J19*$R$686 -> 0 | L19: 908890
D20: =SUM(D16:D19)/4 -> 3.809213
D22: =E22/J22 -> 3.9256198 | E22: =(F22*1000000/8) -> 140125 | F22: 1.121 | G22: 24267 | H22: 589373156 | I22: 589408851 | J22: =I22-H22 -> 35695 | K22: =J22*$R$686 -> 0 | L22: 908890
D23: =E23/J23 -> 3.9579968 | E23: =(F23*1000000/8) -> 147000 | F23: 1.176 | G23: 267_2 | H23: 589408851 | I23: 589445991 | J23: =I23-H23 -> 37140 | K23: =J23*$R$686 -> 0 | L23: 908890
D24: =E24/J24 -> 3.791876 | E24: =(F24*1000000/8) -> 226375 | F24: 1.811 | G24: 268_1 | H24: 589445991 | I24: 589505691 | J24: =I24-H24 -> 59700 | K24: =J24*$R$686 -> 0 | L24: 908890
D25: =E25/J25 -> 3.7168561 | E25: =(F25*1000000/8) -> 294375 | F25: 2.355 | G25: 268_2 | H25: 589505691 | I25: 589584891 | J25: =I25-H25 -> 79200 | K25: =J25*$R$686 -> 0 | L25: 908890
D26: =E26/J26 -> 3.860252 | E26: =(F26*1000000/8) -> 337000 | F26: 2.696 | G26: 269_1 | H26: 589584891 | I26: 589672191 | J26: =I26-H26 -> 87300 | K26: =J26*$R$686 -> 0 | L26: 908890
D27: =E27/J27 -> 3.8356051 | E27: =(F27*1000000/8) -> 346125 | F27: 2.769 | G27: 270_1 | H27: 589672191 | I27: 589762431 | J27: =I27-H27 -> 90240 | K27: =J27*$R$686 -> 0 | L27: 908890
D28: =E28/J28 -> 3.7087579 | E28: =(F28*1000000/8) -> 305750 | F28: 2.446 | G28: 271_1 | H28: 589762431 | I28: 589844871 | J28: =I28-H28 -> 82440 | K28: =J28*$R$686 -> 0 | L28: 908890
D29: =SUM(D22:D28)/7 -> 3.8281377

Sheet Sheet1
W1: 108 channels
W2: 64 samples at 20 sec per sample
G4: burst sys tic | H4: n2 mon | I4: n1 | J4: n2 | K4: n3 | L4: n1/n2 | M4: n3/n2 | N4: n2/n2mon | O4: 10*bst/n2 | P4: 10*bst/n2m | Q4: n2mon/10 | R4: n1/10 | S4: n2/10 | T4: n3/10 | W4: =108*64*20 -> 138240 | X4: =W4/3600 -> 38.4
A6: TEST1 | G6: 180 | H6: 20 | I6: 100 | J6: 100 | K6: 7200 | L6: =I6/J6 -> 1 | M6: =K6/J6 -> 72 | N6: =J6/H6 -> 5 | O6: =10*G6/J6 -> 18 | P6: =10*G6/H6 -> 90 | Q6: =H6/10 -> 2 | R6: =I6/10 -> 10 | S6: =J6/10 -> 10 | T6: =K6/10 -> 720
E7: 4PEP | F7: act 3 | G7: 180 | H7: 20 | I7: 101 | J7: 101 | K7: 7201 | L7: =I7/J7 -> 1 | M7: =K7/J7 -> 71.29703 | N7: =J7/H7 -> 5.05 | O7: =10*G7/J7 -> 17.821782 | P7: =10*G7/H7 -> 90 | Q7: =H7/10 -> 2 | R7: =I7/10 -> 10.1 | S7: =J7/10 -> 10.1 | T7: =K7/10 -> 720.1
E8: 6PEP | F8: act 5 | G8: 180 | H8: 20 | I8: 99 | J8: 99 | K8: 7199 | L8: =I8/J8 -> 1 | M8: =K8/J8 -> 72.717172 | N8: =J8/H8 -> 4.95 | O8: =10*G8/J8 -> 18.181818 | P8: =10*G8/H8 -> 90 | Q8: =H8/10 -> 2 | R8: =I8/10 -> 9.9 | S8: =J8/10 -> 9.9 | T8: =K8/10 -> 719.9 | Z8: =24*10*180*0.2 -> 8640
E9: 7PEP | F9: act 6 | G9: 180 | H9: 20 | I9: 400 | J9: 400 | K9: 7200 | L9: =I9/J9 -> 1 | M9: =K9/J9 -> 18 | N9: =J9/H9 -> 20 | O9: =10*G9/J9 -> 4.5 | P9: =10*G9/H9 -> 90 | Q9: =H9/10 -> 2 | R9: =I9/10 -> 40 | S9: =J9/10 -> 40 | T9: =K9/10 -> 720 | V9: Thresh = 24 * 10 * ID40 * CPS | Z9: =8640/(24*10*200) -> 0.18
E10: 8PEP | F10: act 7 | G10: 180 | H10: 20 | I10: 500 | J10: 400 | K10: 7200 | L10: =I10/J10 -> 1.25 | M10: =K10/J10 -> 18 | N10: =J10/H10 -> 20 | O10: =10*G10/J10 -> 4.5 | P10: =10*G10/H10 -> 90 | Q10: =H10/10 -> 2 | R10: =I10/10 -> 50 | S10: =J10/10 -> 40 | T10: =K10/10 -> 720
D11: 540496956 | E11: 9PEP | F11: act 8 | G11: 180 | H11: 20 | I11: 501 | J11: 405 | K11: 7201 | L11: =I11/J11 -> 1.237037 | M11: =K11/J11 -> 17.780247 | N11: =J11/H11 -> 20.25 | O11: =10*G11/J11 -> 4.4444444 | P11: =10*G11/H11 -> 90 | Q11: =H11/10 -> 2 | R11: =I11/10 -> 50.1 | S11: =J11/10 -> 40.5 | T11: =K11/10 -> 720.1
C12: =D12-D11 -> 405 | D12: 540497361 | E12: 10PEP | F12: act 9
F15: test2 | G15: 180 | H15: 20 | I15: 100 | J15: 100 | K15: 7200 | L15: =I15/J15 -> 1 | M15: =K15/J15 -> 72 | N15: =J15/H15 -> 5 | O15: =10*G15/J15 -> 18 | P15: =10*G15/H15 -> 90 | Q15: =H15/10 -> 2 | R15: =I15/10 -> 10 | S15: =J15/10 -> 10 | T15: =K15/10 -> 720
G16: 180 | H16: 20 | I16: 101 | J16: 101 | K16: 7201 | L16: =I16/J16 -> 1 | M16: =K16/J16 -> 71.29703 | N16: =J16/H16 -> 5.05 | O16: =10*G16/J16 -> 17.821782 | P16: =10*G16/H16 -> 90 | Q16: =H16/10 -> 2 | R16: =I16/10 -> 10.1 | S16: =J16/10 -> 10.1 | T16: =K16/10 -> 720.1
G17: 180 | H17: 20 | I17: 99 | J17: 99 | K17: 7199 | L17: =I17/J17 -> 1 | M17: =K17/J17 -> 72.717172 | N17: =J17/H17 -> 4.95 | O17: =10*G17/J17 -> 18.181818 | P17: =10*G17/H17 -> 90 | Q17: =H17/10 -> 2 | R17: =I17/10 -> 9.9 | S17: =J17/10 -> 9.9 | T17: =K17/10 -> 719.9
G18: 180 | H18: 20 | I18: 400 | J18: 400 | K18: 7200 | L18: =I18/J18 -> 1 | M18: =K18/J18 -> 18 | N18: =J18/H18 -> 20 | O18: =10*G18/J18 -> 4.5 | P18: =10*G18/H18 -> 90 | Q18: =H18/10 -> 2 | R18: =I18/10 -> 40 | S18: =J18/10 -> 40 | T18: =K18/10 -> 720
G19: 180 | H19: 20 | I19: 500 | J19: 400 | K19: 7200 | L19: =I19/J19 -> 1.25 | M19: =K19/J19 -> 18 | N19: =J19/H19 -> 20 | O19: =10*G19/J19 -> 4.5 | P19: =10*G19/H19 -> 90 | Q19: =H19/10 -> 2 | R19: =I19/10 -> 50 | S19: =J19/10 -> 40 | T19: =K19/10 -> 720
G20: 180 | H20: 20 | I20: 501 | J20: 405 | K20: 7201 | L20: =I20/J20 -> 1.237037 | M20: =K20/J20 -> 17.780247 | N20: =J20/H20 -> 20.25 | O20: =10*G20/J20 -> 4.4444444 | P20: =10*G20/H20 -> 90 | Q20: =H20/10 -> 2 | R20: =I20/10 -> 50.1 | S20: =J20/10 -> 40.5 | T20: =K20/10 -> 720.1

Sheet status tracker
A3: LOAD | B3: DOY | C3: ON/OFF | D3: Reset | E3: Trigger | F3: Bursts | G3: Threshold | H3: Trigger | I3: Burst | J3: Burst | K3: N1 | L3: N2 | M3: N3 | N3: Status | O3: GNC Flag | P3: NOTES
D4: Trig Cntr | E4: Count | F4: Allowed | G4: (cps) | H4: Triggered | I4: Recorded | J4: Playback
A5: 23064 | B5: 64 | C5: Pwr On | D5: Y | E5: 0 | F5: 6 | K5: 180 | L5: 180 | M5: 7200 | N5: 1800 | O5: DIS | P5: First power on post hibernation
B6: 69 | C6: Pwr Off
B7: 69 | C7: Pwr On | D7: Y | E7: 0 | F7: 6 | K7: 180 | L7: 180 | M7: 7200 | N7: 1800 | O7: DIS
A8: 23086 | B8: 105 | C8: Pwr Off
A9: 23107 | B9: 109 | C9: Pwr On | D9: Y | E9: 0 | F9: 6 | K9: 180 | L9: 180 | M9: 7200 | N9: 1800 | O9: DIS
A10: 23135 | B10: 141 | C10: Pwr Off
A11: 23149 | B11: 150 | C11: Pwr On | D11: Y | E11: 0 | F11: 3 | G11: 0.01 | K11: 100 | L11: 100 | M11: 7200 | N11: 1800 | O11: DIS | P11: Updated rates, set threshold to super low, updated burst limit to 3
B12: 151 | E12: 1 | F12: 3 | G12: 0.01 | H12: Y | I12: Y | J12: can erase? | P12: burst #1
B13: 153 | E13: 2 | F13: 3 | G13: 0.01 | H13: Y | I13: Y | J13: pb ths too? | P13: burst #2
B14: 155 | E14: 3 | F14: 3 | G14: 0.01 | H14: Y | I14: Y | J14: 24057? | P14: burst #3
B15: 157 | E15: 4 | F15: 3 | H15: Y | I15: N | P15: 4th trigger exceeded burst limit, this advanced trigger count to 4, but did not record anything
B16: 170 | D16: N | F16: 6 | G16: 0.2 | P16: set threshold to .2, upped limit to 6, did not reset trigger counter
A17: 23170 | B17: 182 | D17: N | E17: 5 | F17: 6 | G17: 0.2 | H17: Y | I17: Y | J17: 23-344 | P17: burst #4
A18: 23191 | B18: 194 | E18: 6 | F18: 6 | G18: 0.2 | H18: Y | I18: Y | J18: 23-359 | P18: burst #5
A19: 23212 | B19: 216 | C19: Pwr Off
B20: 221 | C20: Pwr On | D20: N | F20: 6 | G20: 1.5 | K20: 100 | L20: 100 | M20: 7200 | N20: 1800 | O20: ENA | P20: GNC flag enabled first time - after entering 3-axis mode
A21: 23233 | B21: 231 | C21: Pwr Off
B22: 234 | C22: Pwr On | D22: N | F22: 12 | G22: 1.5 | K22: 100 | L22: 100 | M22: 7200 | N22: 1800 | O22: ENA | P22: 3-axis
A23: 23245 | B23: 254 | C23: Pwr Off
B24: 247 | C24: Pwr On | D24: N | F24: 12 | G24: 1.5 | K24: 100 | L24: 100 | M24: 7200 | N24: 1800 | O24: ENA | P24: 3-axis
A25: 23254 | B25: 260 | C25: Pwr Off
B26: 261 | C26: Pwr On | D26: N | F26: 12 | G26: 1.5 | K26: 100 | L26: 100 | M26: 7200 | N26: 1800 | O26: ENA | P26: 3-axis
B27: 263 | C27: Pwr Off
B28: 266 | C28: Pwr On | D28: N | F28: 12 | G28: 1.5 | K28: 100 | L28: 100 | M28: 7200 | N28: 1800 | O28: ENA | P28: 3-axis
B29: 269 | C29: Pwr Off
B30: 270 | C30: Pwr On | D30: N | F30: 12 | G30: 1.5 | K30: 100 | L30: 100 | M30: 7200 | N30: 1800 | O30: DIS | P30: Disable after returning to spinning mode
A31: 23275 | B31: 275 | G31: 0.4 | P31: Update threshold to .4 cps
A32: 23296 | B32: 311 | E32: 7 | F32: 12 | H32: Y | I32: Y | J32: 23-362 | P32: burst #6
A33: 24015 | B33: 15 | D33: N | F33: 13 | G33: 0.4 | P33: Update bursts allowed to 13
A34: 24036 | B34: 41 | C34: Pwr Off
A35: 24036 | B35: 41 | C35: Pwr On | D35: N | F35: 13 | G35: 1.5 | K35: 100 | L35: 100 | M35: 7200 | N35: 1800 | O35: DIS
A36: 24036 | B36: 48 | C36: Pwr Off
A37: 24036 | B37: 48 | C37: Pwr On | D37: N | F37: 13 | G37: 1.5 | K37: 100 | L37: 100 | M37: 7200 | N37: 1800 | O37: DIS

Sheet totals
C5: bytes/sec | D5: bytes
A6: doy 0 - 50 | B6: 50 | C6: 2.0494444 | D6: =B6*3600*24*C6 -> 8853600 | E6: =D6*8/1000000 -> 70.8288
B7: 23170 | C7: 2.0494444 | D7: 23446877 | E7: =D7*8/1000000 -> 187.57502
B8: 23191 | C8: 3.382775 | D8: 22217222 | E8: =D8*8/1000000 -> 177.73778 | H8: switch to new rate during 23191
B9: 23212 | D9: 3687498.8 | E9: =D9*8/1000000 -> 29.49999
B10: 23338 | D10: 18829320 | E10: =D10*8/1000000 -> 150.63456
B11: 23360 | D11: 24734847 | E11: =D11*8/1000000 -> 197.87878
A12: doy 353-365 | B12: 12 | C12: 3.382775 | D12: =B12*3600*24*C12 -> 3507261.1 | E12: =D12*8/1000000 -> 28.058089
D13: =SUM(D6:D12) -> 1.0527663e+08 | E13: =SUM(E6:E12) -> 842.21301

Sheet 22144-hibernation 2022 +
C2: V4 operation in sequence 22080
H3: packet size (bits)
H4: max bits | I4: historical size | J4: Enabled? | K4: integration time (s) | L4: bps | M4: sec/day | N4: data collection (days) | P4: Total recorded data (Mbits)/year | Q4: Total downlinked data (Mbits)/year
F5: Survey Data
G6: N1 | H6: 5680 | I6: 2400 | J6: 1 | K6: 3600 | L6: =J6*I6/K6 -> 0.66666667 | M6: =3600*24 -> 86400 | N6: 22 | P6: =L6*M6*N6/1000000 -> 1.2672 | Q6: =P6 -> 1.2672
G7: N2 normal | H7: 4928 | I7: 1920 | J7: 1 | K7: 90 | L7: =J7*I7/K7 -> 21.333333 | M7: =3600*24 -> 86400 | N7: =N6 -> 22 | P7: =L7*M7*N7/1000000 -> 40.5504 | Q7: =P7 -> 40.5504
G8: N3+ extra | H8: 64000 | I8: 20000 | J8: 1 | K8: 7200 | L8: =J8*I8/K8 -> 2.7777778 | M8: =3600*24 -> 86400 | N8: =N6 -> 22 | P8: =L8*M8*N8/1000000 -> 5.28 | Q8: =P8 -> 5.28
G9: HK/status | H9: 512 | I9: =H9 -> 512 | J9: 1 | K9: 1800 | L9: =J9*I9/K9 -> 0.28444444 | M9: =3600*24 -> 86400 | N9: =N6 -> 22 | P9: =L9*M9*N9/1000000 -> 0.540672 | Q9: =P9 -> 0.540672
K10: =IF(AND( (K6/K7)=INT(K6/K7), (K8/K7)=INT(K8/K7) ), " ", "error") | P10: =SUM(P6:P9) -> 47.638272 | Q10: =SUM(Q6:Q9) -> 47.638272
H12: max bits | I12: historical size | J12: Enabled? | K12: integration time (s) | L12: bps | M12: sec/day | P12: Total recorded data (Mbits)/year | Q12: Total downlinked data (Mbits)/year
F13: Burst Data
G14: High Time Resolution Buffered Rate (10) Data | H14: 8480 | I14: 2900 | J14: 1 | K14: =I22*64 -> 1280 | L14: =J14*I14/K14 -> 2.265625 | M14: =3600*24 -> 86400 | P14: =L14*M14*I25*((I23+I24))/1000000 -> 0 | Q14: =L14*M14*I26*((I23+I24))/1000000 -> 0
G15: Trigger assessment data | H15: 992 | I15: 600 | J15: 1 | K15: =I22*64 -> 1280 | L15: =J15*I15/K15 -> 0.46875 | M15: =3600*24 -> 86400 | P15: =L15*M15*I25*((I23+I24))/1000000 -> 0 | Q15: =L15*M15*I26*((I23+I24))/1000000 -> 0
G16: N2 burst data | H16: =H7 -> 4928 | I16: 1400 | J16: 1 | K16: =I22 -> 20 | L16: =J16*I16/K16 -> 70 | M16: =3600*24 -> 86400 | P16: =L16*M16*I25*I24/1000000 -> 0 | Q16: =L16*M16*I26*I24/1000000 -> 0
P17: =SUM(P14:P16) -> 0 | Q17: =SUM(Q14:Q16) -> 0
F19: Total | P19: =P10+P17 -> 47.638272 | Q19: =Q10+Q17 -> 47.638272 | R19: Mbits
F21: Assumptions
F22: Commanded N2Monitor int time | I22: 20
F23: pre-trigger data (days) | I23: =0.7*I22/10 -> 1.4
F24: post-trigger data (days) | I24: 2
F25: Number of bursts occurring/year assumed | I25: 0
F26: # of N2 bursts downlinked/year assumed | I26: 0
Y28: No MLI
N29: =1/30/24 -> 0.0013888889
C32: Power On Portion of V5 load and test
H33: packet size (bits)
H34: max bits | I34: historical size | J34: Enabled? | K34: integration time (s) | L34: bps | M34: sec/day | N34: data collection (days) | P34: Total recorded data (Mbits)/year | Q34: Total downlinked data (Mbits)/year
F35: Survey Data
G36: N1 | H36: 5680 | I36: 3200 | J36: 1 | K36: 3600 | L36: =J36*I36/K36 -> 0.88888889 | M36: =3600*24 -> 86400 | N36: =1/24 -> 0.041666667 | P36: =L36*M36*N36/1000000 -> 0.0032 | Q36: =P36 -> 0.0032
G37: N2 normal | H37: 4928 | I37: 1920 | J37: 1 | K37: 90 | L37: =J37*I37/K37 -> 21.333333 | M37: =3600*24 -> 86400 | N37: =N36 -> 0.041666667 | P37: =L37*M37*N37/1000000 -> 0.0768 | Q37: =P37 -> 0.0768
C38: The historical size of the packets | G38: N3+ extra | H38: 64000 | I38: 32080 | J38: 1 | K38: 7200 | L38: =J38*I38/K38 -> 4.4555556 | M38: =3600*24 -> 86400 | N38: =N36 -> 0.041666667 | P38: =L38*M38*N38/1000000 -> 0.01604 | Q38: =P38 -> 0.01604
C39: probably are too high. | E39: --> | G39: HK/status | H39: 512 | I39: =H39 -> 512 | J39: 1 | K39: 1 | L39: =J39*I39/K39 -> 512 | M39: =3600*24 -> 86400 | N39: =N36 -> 0.041666667 | P39: =L39*M39*N39/1000000 -> 1.8432 | Q39: =P39 -> 1.8432
K40: =IF(AND( (K36/K37)=INT(K36/K37), (K38/K37)=INT(K38/K37) ), " ", "error") | P40: =SUM(P36:P39) -> 1.93924 | Q40: =SUM(Q36:Q39) -> 1.93924
H42: max bits | I42: historical size | J42: Enabled? | K42: integration time (s) | L42: bps | M42: sec/day | P42: Total recorded data (Mbits)/year | Q42: Total downlinked data (Mbits)/year
F43: Burst Data
G44: High Time Resolution Buffered Rate (10) Data | H44: 8480 | I44: =I$14 -> 2900 | J44: 1 | K44: =I52*64 -> 1280 | L44: =J44*I44/K44 -> 2.265625 | M44: =3600*24 -> 86400 | P44: =L44*M44*I55*((I53+I54))/1000000 -> 0 | Q44: =L44*M44*I56*((I53+I54))/1000000 -> 0
G45: Trigger assessment data | H45: 992 | I45: =I$15 -> 600 | J45: 1 | K45: =I52*64 -> 1280 | L45: =J45*I45/K45 -> 0.46875 | M45: =3600*24 -> 86400 | P45: =L45*M45*I55*((I53+I54))/1000000 -> 0 | Q45: =L45*M45*I56*((I53+I54))/1000000 -> 0
G46: N2 burst data | H46: =H37 -> 4928 | I46: =I$16 -> 1400 | J46: 1 | K46: =I52 -> 20 | L46: =J46*I46/K46 -> 70 | M46: =3600*24 -> 86400 | P46: =L46*M46*I55*I54/1000000 -> 0 | Q46: =L46*M46*I56*I54/1000000 -> 0
P47: =SUM(P44:P46) -> 0 | Q47: =SUM(Q44:Q46) -> 0
F49: Total | P49: =P40+P47 -> 1.93924 | Q49: =Q40+Q47 -> 1.93924 | R49: Mbits
...

Sheet 24267_pepssi
A1: 267 23:04:12 | B1: 267 14:48:11 | C1: 589408807 | D1: 1 | E1: C&DH #1 | F1: TT 21 | G1: SSR_LO_RCRD_SYNC PEPSSI_DT3 | I1: TRK_267_2
A2: 267 23:04:15 | B2: 267 14:48:14 | C2: 589408810 | D2: 1 | E2: C&DH #1 | F2: TT 21 | G2: SSR_LO_RCRD_SYNC PEPSSI_DT4 | I2: TRK_267_2
A3: 267 23:04:35 | B3: 267 14:48:34 | C3: 589408830 | D3: 1 | E3: C&DH #1 | F3: TT 22 | G3: SSR_LO_RCRD_SYNC PEPSSI_DT1
A4: 267 23:04:38 | B4: 267 14:48:37 | C4: 589408833 | D4: 1 | E4: C&DH #1 | F4: TT 22 | G4: SSR_LO_RCRD_SYNC PEPSSI_DT2
A5: 268 09:23:17 | B5: 268 01:07:11 | C5: 589445947 | D5: 1 | E5: C&DH #1 | F5: TT 34 | G5: SSR_LO_RCRD_SYNC PEPSSI_DT3 | I5: TRK_268_1
A6: 268 09:23:20 | B6: 268 01:07:14 | C6: 589445950 | D6: 1 | E6: C&DH #1 | F6: TT 34 | G6: SSR_LO_RCRD_SYNC PEPSSI_DT4 | I6: TRK_268_1
A7: 268 09:23:40 | B7: 268 01:07:34 | C7: 589445970 | D7: 1 | E7: C&DH #1 | F7: TT 35 | G7: SSR_LO_RCRD_SYNC PEPSSI_DT1
